Workbook

Sheet Paste
A1: Inf | B1: Name | C1: Age | D1: CA | E1: PA | F1: Nationalities | G1: Club | H1: Asking Price | I1: Positions | J1: Actual Rating | K1: Potential Rating | L1: Striker | M1: AM(L) | N1: AM(C) | O1: AM(R) | P1: DM | Q1: D(L) | R1: D(C) | S1: D(R) | T1: GK | U1: Accelereation | V1: Agility | W1: Balance | X1: Jumping | Y1: Left Foot | Z1: Natural Fitness | AA1: Pace | AB1: Right Foot | AC1: Stamina | AD1: Strength | AE1: Aerial Ability | AF1: Command of Area | AG1: Communication | AH1: Eccentricity | AI1: Handling | AJ1: Kicking | AK1: One on Ones | AL1: Reflexes | AM1: Rushing Out | AN1: Tendency to Punch | AO1: Throwing | AP1: Aggression | AQ1: Anticipation | AR1: Bravery | AS1: Composure | AT1: Concentration | AU1: Decisions | AV1: Determination | AW1: Flair | AX1: Leadership | AY1: Off the Ball | AZ1: Positioning | BA1: Teamwork | BB1: Vision | BC1: Workrate | BD1: Corners | BE1: Crossing | BF1: Dribbling | BG1: Finishing | BH1: First Touch | BI1: Freekicks | BJ1: Heading | BK1: Long Shots | BL1: Long Throws | BM1: Marking | BN1: Passing | BO1: Penalty Taking | BP1: Tackling | BQ1: Technique
B2: Scot Little | C2: 16 | D2: 79 | E2: 163 | F2: Scotland,England | G2: Brixham | H2: £2,676 | I2: ST | J2: 55.1 | K2: 81.83 | L2: 20 | M2: 15 | N2: 1 | O2: 9 | P2: 1 | Q2: 1 | R2: 1 | S2: 1 | T2: 1 | U2: 11 | V2: 12 | W2: £13 | X2: 5 | Y2: 20 | Z2: 13 | AA2: 12 | AB2: 13 | AC2: 10 | AD2: 2 | AE2: 1 | AF2: 1 | AG2: 3 | AH2: 3 | AI2: 2 | AJ2: 2 | AK2: 3 | AL2: 3 | AM2: 1 | AN2: 1 | AO2: 2 | AP2: 11 | AQ2: 9 | AR2: 4 | AS2: 11 | AT2: 7 | AU2: 10 | AV2: 3 | AW2: 14 | AX2: 5 | AY2: 12 | AZ2: 4 | BA2: 15 | BB2: 8 | BC2: 15 | BD2: 8 | BE2: 11 | BF2: 10 | BG2: 14 | BH2: 14 | BI2: 6 | BJ2: 7 | BK2: 7 | BL2: 2 | BM2: 2 | BN2: 9 | BO2: 8 | BP2: 1 | BQ2: 14
B3: Alan Hackney | C3: 16 | D3: 89 | E3: 177 | F3: England | G3: Brixham | H3: £12,105 | I3: DM/M C | J3: 53.16 | K3: 78.5 | L3: 4 | M3: 1 | N3: 9 | O3: 1 | P3: 16 | Q3: 1 | R3: 1 | S3: 1 | T3: 1 | U3: 8 | V3: 9 | W3: £14 | X3: 5 | Y3: 13 | Z3: 16 | AA3: 9 | AB3: 20 | AC3: 8 | AD3: 7 | AE3: 1 | AF3: 3 | AG3: 1 | AH3: 3 | AI3: 2 | AJ3: 3 | AK3: 1 | AL3: 1 | AM3: 2 | AN3: 3 | AO3: 2 | AP3: 12 | AQ3: 10 | AR3: 15 | AS3: 12 | AT3: 7 | AU3: 15 | AV3: 16 | AW3: 12 | AX3: 11 | AY3: 11 | AZ3: 6 | BA3: 10 | BB3: 12 | BC3: 13 | BD3: 8 | BE3: 11 | BF3: 8 | BG3: 10 | BH3: 14 | BI3: 11 | BJ3: 6 | BK3: 8 | BL3: 4 | BM3: 5 | BN3: 12 | BO3: 8 | BP3: 6 | BQ3: 14
B4: Marc Mitchell | C4: 16 | D4: 85 | E4: 158 | F4: Grenada,England | G4: Brixham | H4: £2,908 | I4: AM LC | J4: 53.16 | K4: 77.37 | L4: 1 | M4: 8 | N4: 20 | O4: 8 | P4: 12 | Q4: 1 | R4: 1 | S4: 1 | T4: 1 | U4: 10 | V4: 11 | W4: £15 | X4: 12 | Y4: 12 | Z4: 6 | AA4: 11 | AB4: 20 | AC4: 12 | AD4: 6 | AE4: 3 | AF4: 1 | AG4: 2 | AH4: 3 | AI4: 2 | AJ4: 2 | AK4: 2 | AL4: 1 | AM4: 1 | AN4: 2 | AO4: 3 | AP4: 7 | AQ4: 11 | AR4: 9 | AS4: 11 | AT4: 7 | AU4: 9 | AV4: 10 | AW4: 14 | AX4: 2 | AY4: 10 | AZ4: 8 | BA4: 9 | BB4: 11 | BC4: 14 | BD4: 8 | BE4: 12 | BF4: 9 | BG4: 9 | BH4: 14 | BI4: 6 | BJ4: 5 | BK4: 7 | BL4: 4 | BM4: 6 | BN4: 13 | BO4: 5 | BP4: 4 | BQ4: 11
B5: Paul Stroud | C5: 16 | D5: 77 | E5: 156 | F5: England | G5: Brixham | H5: £2,613 | I5: AM/ST RC | J5: 51.25 | K5: 76.35 | L5: 20 | M5: 1 | N5: 15 | O5: 16 | P5: 1 | Q5: 1 | R5: 1 | S5: 1 | T5: 1 | U5: 13 | V5: 10 | W5: £14 | X5: 8 | Y5: 11 | Z5: 17 | AA5: 12 | AB5: 20 | AC5: 12 | AD5: 4 | AE5: 3 | AF5: 4 | AG5: 1 | AH5: 2 | AI5: 2 | AJ5: 3 | AK5: 3 | AL5: 1 | AM5: 3 | AN5: 2 | AO5: 2 | AP5: 6 | AQ5: 10 | AR5: 8 | AS5: 5 | AT5: 5 | AU5: 7 | AV5: 12 | AW5: 14 | AX5: 11 | AY5: 9 | AZ5: 4 | BA5: 12 | BB5: 10 | BC5: 7 | BD5: 4 | BE5: 6 | BF5: 14 | BG5: 5 | BH5: 12 | BI5: 5 | BJ5: 5 | BK5: 8 | BL5: 1 | BM5: 7 | BN5: 11 | BO5: 6 | BP5: 4 | BQ5: 14
B6: Hisashi Roddy | C6: 16 | D6: 78 | E6: 158 | F6: England | G6: Brixham | H6: £2,713 | I6: D/WB RL | J6: 51.03 | K6: 76.01 | L6: 1 | M6: 1 | N6: 1 | O6: 1 | P6: 1 | Q6: 16 | R6: 1 | S6: 20 | T6: 1 | U6: 12 | V6: 11 | W6: £14 | X6: 11 | Y6: 15 | Z6: 18 | AA6: 10 | AB6: 20 | AC6: 14 | AD6: 6 | AE6: 3 | AF6: 4 | AG6: 1 | AH6: 3 | AI6: 1 | AJ6: 1 | AK6: 1 | AL6: 2 | AM6: 1 | AN6: 3 | AO6: 1 | AP6: 14 | AQ6: 10 | AR6: 15 | AS6: 6 | AT6: 9 | AU6: 9 | AV6: 11 | AW6: 8 | AX6: 6 | AY6: 9 | AZ6: 9 | BA6: 8 | BB6: 10 | BC6: 13 | BD6: 1 | BE6: 7 | BF6: 5 | BG6: 1 | BH6: 8 | BI6: 1 | BJ6: 5 | BK6: 2 | BL6: 3 | BM6: 9 | BN6: 7 | BO6: 3 | BP6: 13 | BQ6: 13
B7: Ashley Sarahs | C7: 16 | D7: 71 | E7: 146 | F7: England,Northern Ireland | G7: Brixham | H7: £1,980 | I7: GK | J7: 51.89 | K7: 75.58 | L7: 1 | M7: 1 | N7: 1 | O7: 1 | P7: 1 | Q7: 1 | R7: 1 | S7: 1 | T7: 20 | U7: 10 | V7: 10 | W7: £8 | X7: 13 | Y7: 16 | Z7: 7 | AA7: 9 | AB7: 20 | AC7: 3 | AD7: 6 | AE7: 9 | AF7: 8 | AG7: 10 | AH7: 2 | AI7: 15 | AJ7: 5 | AK7: 11 | AL7: 14 | AM7: 15 | AN7: 5 | AO7: 5 | AP7: 10 | AQ7: 11 | AR7: 6 | AS7: 4 | AT7: 11 | AU7: 10 | AV7: 8 | AW7: 3 | AX7: 5 | AY7: 3 | AZ7: 6 | BA7: 10 | BB7: 2 | BC7: 7 | BD7: 4 | BE7: 1 | BF7: 3 | BG7: 1 | BH7: 6 | BI7: 6 | BJ7: 1 | BK7: 2 | BL7: 2 | BM7: 1 | BN7: 4 | BO7: 1 | BP7: 1 | BQ7: 11
B8: Aydin Webb | C8: 16 | D8: 68 | E8: 135 | F8: England | G8: Brixham | H8: £2,507 | I8: M/AM RLC | J8: 49.14 | K8: 72.98 | L8: 1 | M8: 16 | N8: 1 | O8: 20 | P8: 12 | Q8: 1 | R8: 1 | S8: 1 | T8: 1 | U8: 7 | V8: 8 | W8: £7 | X8: 8 | Y8: 10 | Z8: 14 | AA8: 8 | AB8: 20 | AC8: 12 | AD8: 7 | AE8: 2 | AF8: 2 | AG8: 3 | AH8: 1 | AI8: 1 | AJ8: 3 | AK8: 1 | AL8: 2 | AM8: 1 | AN8: 1 | AO8: 3 | AP8: 11 | AQ8: 5 | AR8: 9 | AS8: 9 | AT8: 11 | AU8: 13 | AV8: 18 | AW8: 10 | AX8: 7 | AY8: 10 | AZ8: 6 | BA8: 14 | BB8: 12 | BC8: 13 | BD8: 4 | BE8: 8 | BF8: 7 | BG8: 10 | BH8: 15 | BI8: 6 | BJ8: 4 | BK8: 8 | BL8: 3 | BM8: 6 | BN8: 10 | BO8: 4 | BP8: 9 | BQ8: 11
B9: Daniel Willard | C9: 16 | D9: 74 | E9: 149 | F9: England,Northern Ireland | G9: Brixham | H9: £9,312 | I9: AM L | J9: 48.14 | K9: 71.89 | L9: 4 | M9: 20 | N9: 3 | O9: 1 | P9: 1 | Q9: 1 | R9: 1 | S9: 1 | T9: 1 | U9: 13 | V9: 15 | W9: £10 | X9: 8 | Y9: 20 | Z9: 5 | AA9: 13 | AB9: 11 | AC9: 12 | AD9: 5 | AE9: 3 | AF9: 1 | AG9: 1 | AH9: 2 | AI9: 1 | AJ9: 1 | AK9: 1 | AL9: 2 | AM9: 3 | AN9: 1 | AO9: 1 | AP9: 7 | AQ9: 6 | AR9: 10 | AS9: 7 | AT9: 6 | AU9: 6 | AV9: 18 | AW9: 12 | AX9: 5 | AY9: 8 | AZ9: 4 | BA9: 6 | BB9: 11 | BC9: 7 | BD9: 6 | BE9: 4 | BF9: 8 | BG9: 10 | BH9: 11 | BI9: 10 | BJ9: 6 | BK9: 5 | BL9: 4 | BM9: 2 | BN9: 10 | BO9: 6 | BP9: 4 | BQ9: 10
B10: Allan Hall | C10: 16 | D10: 71 | E10: 146 | F10: England,Australia | G10: Brixham | H10: £2,328 | I10: DM/M C | J10: 45.22 | K10: 68.33 | L10: 1 | M10: 1 | N10: 16 | O10: 6 | P10: 16 | Q10: 1 | R10: 1 | S10: 1 | T10: 1 | U10: 13 | V10: 14 | W10: £10 | X10: 4 | Y10: 12 | Z10: 13 | AA10: 12 | AB10: 20 | AC10: 13 | AD10: 4 | AE10: 3 | AF10: 1 | AG10: 2 | AH10: 2 | AI10: 2 | AJ10: 2 | AK10: 1 | AL10: 3 | AM10: 3 | AN10: 4 | AO10: 2 | AP10: 10 | AQ10: 7 | AR10: 13 | AS10: 5 | AT10: 4 | AU10: 9 | AV10: 14 | AW10: 10 | AX10: 1 | AY10: 5 | AZ10: 2 | BA10: 7 | BB10: 11 | BC10: 12 | BD10: 4 | BE10: 8 | BF10: 6 | BG10: 8 | BH10: 8 | BI10: 3 | BJ10: 3 | BK10: 5 | BL10: 3 | BM10: 3 | BN10: 10 | BO10: 5 | BP10: 4 | BQ10: 9
B11: Robbie Gallagher | C11: 19 | D11: 66 | E11: 109 | F11: England | G11: Brixham | H11: £11,298 | I11: ST | J11: 46.57 | K11: 64.94 | L11: 20 | M11: 14 | N11: 1 | O11: 1 | P11: 1 | Q11: 1 | R11: 1 | S11: 3 | T11: 1 | U11: 12 | V11: 9 | W11: £7 | X11: 6 | Y11: 9 | Z11: 10 | AA11: 9 | AB11: 20 | AC11: 11 | AD11: 8 | AE11: 1 | AF11: 1 | AG11: 1 | AH11: 2 | AI11: 3 | AJ11: 2 | AK11: 3 | AL11: 3 | AM11: 3 | AN11: 2 | AO11: 3 | AP11: 13 | AQ11: 11 | AR11: 6 | AS11: 10 | AT11: 4 | AU11: 9 | AV11: 12 | AW11: 4 | AX11: 3 | AY11: 10 | AZ11: 6 | BA11: 5 | BB11: 5 | BC11: 8 | BD11: 4 | BE11: 3 | BF11: 13 | BG11: 9 | BH11: 12 | BI11: 4 | BJ11: 13 | BK11: 4 | BL11: 1 | BM11: 6 | BN11: 4 | BO11: 6 | BP11: 4 | BQ11: 9
B12: Jada Mawongo | C12: 21 | D12: 73 | E12: 97 | F12: Sri Lanka,Democratic Republic of Congo,England | G12: Brixham | H12: £13,932 | I12: D C | J12: 52.03 | K12: 64.9 | L12: 1 | M12: 1 | N12: 1 | O12: 1 | P12: 1 | Q12: 1 | R12: 20 | S12: 10 | T12: 1 | U12: 8 | V12: 5 | W12: £6 | X12: 11 | Y12: 9 | Z12: 7 | AA12: 8 | AB12: 20 | AC12: 5 | AD12: 13 | AE12: 4 | AF12: 1 | AG12: 2 | AH12: 2 | AI12: 1 | AJ12: 3 | AK12: 3 | AL12: 1 | AM12: 2 | AN12: 1 | AO12: 1 | AP12: 15 | AQ12: 7 | AR12: 10 | AS12: 8 | AT12: 12 | AU12: 14 | AV12: 10 | AW12: 6 | AX12: 10 | AY12: 5 | AZ12: 14 | BA12: 5 | BB12: 5 | BC12: 6 | BD12: 3 | BE12: 4 | BF12: 1 | BG12: 1 | BH12: 5 | BI12: 1 | BJ12: 11 | BK12: 4 | BL12: 1 | BM12: 14 | BN12: 1 | BO12: 1 | BP12: 13 | BQ12: 1
B13: Joe Cassidy | C13: 20 | D13: 59 | E13: 93 | F13: Scotland | G13: Brixham | H13: £0 | I13: D C | J13: 43.32 | K13: 58.96 | L13: 1 | M13: 1 | N13: 1 | O13: 1 | P13: 5 | Q13: 1 | R13: 20 | S13: 1 | T13: 1 | U13: 5 | V13: 8 | W13: £6 | X13: 15 | Y13: 10 | Z13: 15 | AA13: 11 | AB13: 20 | AC13: 6 | AD13: 6 | AE13: 4 | AF13: 2 | AG13: 1 | AH13: 3 | AI13: 2 | AJ13: 2 | AK13: 3 | AL13: 2 | AM13: 3 | AN13: 3 | AO13: 1 | AP13: 5 | AQ13: 10 | AR13: 7 | AS13: 6 | AT13: 8 | AU13: 13 | AV13: 12 | AW13: 6 | AX13: 8 | AY13: 5 | AZ13: 13 | BA13: 5 | BB13: 5 | BC13: 5 | BD13: 2 | BE13: 1 | BF13: 1 | BG13: 1 | BH13: 5 | BI13: 1 | BJ13: 8 | BK13: 4 | BL13: 1 | BM13: 13 | BN13: 2 | BO13: 2 | BP13: 7 | BQ13: 1
... B25: Jayden Cumberbatch | C25: 16 | D25: 57 | E25: 144 | F25: Jamaica,England | G25: Brixham | H25: £2,201 | I25: D LC | J25: 49.16 | K25: 73.94 | L25: 1 | M25: 1 | N25: 1 | O25: 1 | P25: 1 | Q25: 16 | R25: 20 | S25: 1 | T25: 1 | U25: 7 | V25: 5 | W25: £11 | X25: 17 | Y25: 12 | Z25: 13 | AA25: 7 | AB25: 20 | AC25: 5 | AD25: 11 | AE25: 2 | AF25: 4 | AG25: 1 | AH25: 2 | AI25: 3 | AJ25: 2 | AK25: 3 | AL25: 2 | AM25: 2 | AN25: 1 | AO25: 1 | AP25: 19 | AQ25: 9 | AR25: 7 | AS25: 2 | AT25: 8 | AU25: 7 | AV25: 14 | AW25: 4 | AX25: 14 | AY25: 4 | AZ25: 6 | BA25: 5 | BB25: 5 | BC25: 6 | BD25: 3 | BE25: 5 | BF25: 3 | BG25: 1 | BH25: 7 | BI25: 6 | BJ25: 13 | BK25: 1 | BL25: 1 | BM25: 13 | BN25: 4 | BO25: 3 | BP25: 11 | BQ25: 12
B26: Jordan Wright | C26: 17 | D26: 45 | E26: 93 | F26: New Zealand,England | H26: (£1) | I26: ST | J26: 42.1 | K26: 63.82 | L26: 20 | M26: 1 | N26: 1 | O26: 1 | P26: 1 | Q26: 1 | R26: 1 | S26: 1 | T26: 1 | U26: 11 | V26: 8 | W26: £11 | X26: 7 | Y26: 20 | Z26: 14 | AA26: 8 | AB26: 12 | AC26: 9 | AD26: 6 | AE26: 2 | AF26: 3 | AG26: 3 | AH26: 2 | AI26: 2 | AJ26: 3 | AK26: 1 | AL26: 1 | AM26: 3 | AN26: 1 | AO26: 2 | AP26: 9 | AQ26: 7 | AR26: 16 | AS26: 7 | AT26: 4 | AU26: 9 | AV26: 5 | AW26: 7 | AX26: 5 | AY26: 8 | AZ26: 2 | BA26: 3 | BB26: 5 | BC26: 7 | BD26: 3 | BE26: 7 | BF26: 11 | BG26: 10 | BH26: 10 | BI26: 1 | BJ26: 6 | BK26: 4 | BL26: 3 | BM26: 3 | BN26: 7 | BO26: 4 | BP26: 2 | BQ26: 9
B27: Maxwell Redman | C27: 16 | D27: 57 | E27: 78 | F27: Australia,England | G27: Brixham | H27: £2,104 | I27: D LC | J27: 49.26 | K27: 62.05 | L27: 1 | M27: 1 | N27: 1 | O27: 1 | P27: 1 | Q27: 15 | R27: 20 | S27: 1 | T27: 1 | U27: 8 | V27: 7 | W27: £13 | X27: 13 | Y27: 20 | Z27: 12 | AA27: 11 | AB27: 7 | AC27: 6 | AD27: 6 | AE27: 1 | AF27: 3 | AG27: 1 | AH27: 1 | AI27: 3 | AJ27: 1 | AK27: 1 | AL27: 3 | AM27: 3 | AN27: 1 | AO27: 3 | AP27: 12 | AQ27: 6 | AR27: 17 | AS27: 7 | AT27: 9 | AU27: 9 | AV27: 14 | AW27: 2 | AX27: 12 | AY27: 3 | AZ27: 11 | BA27: 4 | BB27: 3 | BC27: 7 | BD27: 3 | BE27: 6 | BF27: 4 | BG27: 2 | BH27: 7 | BI27: 3 | BJ27: 11 | BK27: 4 | BL27: 4 | BM27: 12 | BN27: 5 | BO27: 2 | BP27: 10 | BQ27: 7
B28: Karnell Dunton | C28: 17 | D28: 35 | E28: 91 | F28: England | G28: Brixham | H28: £1,581 | I28: ST | J28: 39.24 | K28: 61.58 | L28: 20 | M28: 1 | N28: 1 | O28: 1 | P28: 1 | Q28: 1 | R28: 1 | S28: 1 | T28: 1 | U28: 11 | V28: 7 | W28: £4 | X28: 12 | Y28: 9 | Z28: 12 | AA28: 7 | AB28: 20 | AC28: 6 | AD28: 9 | AE28: 3 | AF28: 3 | AG28: 1 | AH28: 2 | AI28: 4 | AJ28: 3 | AK28: 1 | AL28: 1 | AM28: 3 | AN28: 3 | AO28: 1 | AP28: 10 | AQ28: 5 | AR28: 16 | AS28: 5 | AT28: 3 | AU28: 6 | AV28: 12 | AW28: 16 | AX28: 9 | AY28: 3 | AZ28: 4 | BA28: 10 | BB28: 3 | BC28: 5 | BD28: 5 | BE28: 2 | BF28: 9 | BG28: 7 | BH28: 10 | BI28: 8 | BJ28: 13 | BK28: 3 | BL28: 1 | BM28: 1 | BN28: 9 | BO28: 1 | BP28: 1 | BQ28: 15
B29: Joseph James | C29: 20 | D29: 60 | E29: 80 | F29: England | G29: Brixham | H29: £0 | I29: D RC | J29: 47.13 | K29: 58.91 | L29: 1 | M29: 1 | N29: 1 | O29: 1 | P29: 1 | Q29: 1 | R29: 16 | S29: 20 | T29: 1 | U29: 8 | V29: 9 | W29: £8 | X29: 13 | Y29: 10 | Z29: 11 | AA29: 11 | AB29: 20 | AC29: 6 | AD29: 7 | AE29: 1 | AF29: 1 | AG29: 3 | AH29: 3 | AI29: 3 | AJ29: 2 | AK29: 2 | AL29: 3 | AM29: 1 | AN29: 3 | AO29: 4 | AP29: 15 | AQ29: 7 | AR29: 11 | AS29: 12 | AT29: 7 | AU29: 12 | AV29: 5 | AW29: 6 | AX29: 4 | AY29: 5 | AZ29: 11 | BA29: 7 | BB29: 3 | BC29: 8 | BD29: 6 | BE29: 6 | BF29: 6 | BG29: 3 | BH29: 8 | BI29: 6 | BJ29: 9 | BK29: 4 | BL29: 10 | BM29: 9 | BN29: 6 | BO29: 1 | BP29: 11 | BQ29: 7
B30: Junior McQuilken | C30: 20 | D30: 40 | E30: 78 | F30: Scotland | G30: Brixham | H30: £0 | I30: D/WB L | J30: 38.84 | K30: 57.46 | L30: 1 | M30: 7 | N30: 1 | O30: 1 | P30: 1 | Q30: 20 | R30: 1 | S30: 1 | T30: 1 | U30: 13 | V30: 13 | W30: £3 | X30: 5 | Y30: 20 | Z30: 15 | AA30: 14 | AB30: 8 | AC30: 8 | AD30: 2 | AE30: 1 | AF30: 3 | AG30: 1 | AH30: 2 | AI30: 2 | AJ30: 3 | AK30: 4 | AL30: 3 | AM30: 2 | AN30: 2 | AO30: 3 | AP30: 10 | AQ30: 7 | AR30: 6 | AS30: 6 | AT30: 6 | AU30: 10 | AV30: 3 | AW30: 7 | AX30: 5 | AY30: 3 | AZ30: 6 | BA30: 7 | BB30: 2 | BC30: 6 | BD30: 3 | BE30: 8 | BF30: 6 | BG30: 2 | BH30: 5 | BI30: 1 | BJ30: 4 | BK30: 4 | BL30: 5 | BM30: 5 | BN30: 8 | BO30: 1 | BP30: 9 | BQ30: 10
B31: Nnaemeka Anyanwu | C31: 20 | D31: 46 | E31: 71 | F31: England | G31: Brixham | H31: £0 | I31: M/AM/ST L | J31: 42.24 | K31: 57.11 | L31: 18 | M31: 20 | N31: 12 | O31: 1 | P31: 1 | Q31: 1 | R31: 1 | S31: 1 | T31: 1 | U31: 13 | V31: 10 | W31: £6 | X31: 5 | Y31: 20 | Z31: 15 | AA31: 12 | AB31: 8 | AC31: 8 | AD31: 3 | AE31: 3 | AF31: 1 | AG31: 4 | AH31: 2 | AI31: 4 | AJ31: 1 | AK31: 3 | AL31: 3 | AM31: 3 | AN31: 1 | AO31: 3 | AP31: 12 | AQ31: 6 | AR31: 5 | AS31: 6 | AT31: 5 | AU31: 9 | AV31: 4 | AW31: 8 | AX31: 10 | AY31: 9 | AZ31: 4 | BA31: 4 | BB31: 5 | BC31: 6 | BD31: 3 | BE31: 6 | BF31: 10 | BG31: 9 | BH31: 4 | BI31: 3 | BJ31: 6 | BK31: 6 | BL31: 3 | BM31: 2 | BN31: 7 | BO31: 4 | BP31: 1 | BQ31: 9
B32: Gabe Reivers | C32: 19 | D32: 52 | E32: 81 | F32: England | G32: Brixham | H32: £0 | I32: M/AM C | J32: 41.79 | K32: 56.76 | L32: 1 | M32: 2 | N32: 17 | O32: 3 | P32: 7 | Q32: 1 | R32: 1 | S32: 1 | T32: 1 | U32: 7 | V32: 11 | W32: £5 | X32: 11 | Y32: 11 | Z32: 7 | AA32: 12 | AB32: 20 | AC32: 7 | AD32: 3 | AE32: 2 | AF32: 1 | AG32: 2 | AH32: 1 | AI32: 1 | AJ32: 1 | AK32: 2 | AL32: 1 | AM32: 1 | AN32: 3 | AO32: 2 | AP32: 10 | AQ32: 7 | AR32: 6 | AS32: 7 | AT32: 5 | AU32: 12 | AV32: 5 | AW32: 12 | AX32: 2 | AY32: 8 | AZ32: 4 | BA32: 5 | BB32: 11 | BC32: 10 | BD32: 4 | BE32: 3 | BF32: 7 | BG32: 8 | BH32: 13 | BI32: 3 | BJ32: 4 | BK32: 5 | BL32: 3 | BM32: 7 | BN32: 6 | BO32: 2 | BP32: 6 | BQ32: 12
B33: Joshua Adepoju | C33: 20 | D33: 53 | E33: 73 | F33: England | G33: Brixham | H33: £0 | I33: AM/ST R | J33: 44.1 | K33: 56.19 | L33: 20 | M33: 1 | N33: 13 | O33: 18 | P33: 1 | Q33: 1 | R33: 1 | S33: 1 | T33: 1 | U33: 11 | V33: 9 | W33: £9 | X33: 6 | Y33: 12 | Z33: 12 | AA33: 11 | AB33: 20 | AC33: 11 | AD33: 8 | AE33: 1 | AF33: 3 | AG33: 1 | AH33: 1 | AI33: 2 | AJ33: 3 | AK33: 1 | AL33: 2 | AM33: 2 | AN33: 1 | AO33: 3 | AP33: 6 | AQ33: 8 | AR33: 6 | AS33: 7 | AT33: 7 | AU33: 6 | AV33: 16 | AW33: 7 | AX33: 5 | AY33: 11 | AZ33: 8 | BA33: 7 | BB33: 6 | BC33: 9 | BD33: 5 | BE33: 7 | BF33: 11 | BG33: 8 | BH33: 7 | BI33: 6 | BJ33: 6 | BK33: 4 | BL33: 6 | BM33: 7 | BN33: 8 | BO33: 5 | BP33: 4 | BQ33: 7
B34: Connor Underhill | C34: 20 | D34: 55 | E34: 63 | F34: England | G34: Brixham | H34: £6,551 | I34: M C | J34: 46.2 | K34: 52.07 | L34: 1 | M34: 1 | N34: 15 | O34: 1 | P34: 3 | Q34: 1 | R34: 1 | S34: 3 | T34: 1 | U34: 9 | V34: 8 | W34: £7 | X34: 6 | Y34: 12 | Z34: 12 | AA34: 10 | AB34: 20 | AC34: 9 | AD34: 6 | AE34: 3 | AF34: 2 | AG34: 1 | AH34: 3 | AI34: 2 | AJ34: 2 | AK34: 2 | AL34: 2 | AM34: 3 | AN34: 3 | AO34: 1 | AP34: 6 | AQ34: 6 | AR34: 3 | AS34: 6 | AT34: 2 | AU34: 12 | AV34: 14 | AW34: 11 | AX34: 12 | AY34: 12 | AZ34: 5 | BA34: 13 | BB34: 8 | BC34: 8 | BD34: 5 | BE34: 7 | BF34: 6 | BG34: 8 | BH34: 14 | BI34: 5 | BJ34: 5 | BK34: 6 | BL34: 3 | BM34: 7 | BN34: 12 | BO34: 3 | BP34: 3 | BQ34: 12
B35: Scott Aldridge | C35: 16 | D35: 54 | E35: 59 | F35: England | G35: Brixham | H35: £1,914 | I35: M/AM RL | J35: 40.61 | K35: 44.06 | L35: 1 | M35: 12 | N35: 1 | O35: 16 | P35: 1 | Q35: 1 | R35: 1 | S35: 1 | T35: 1 | U35: 15 | V35: 12 | W35: £6 | X35: 5 | Y35: 11 | Z35: 16 | AA35: 13 | AB35: 20 | AC35: 9 | AD35: 3 | AE35: 3 | AF35: 3 | AG35: 1 | AH35: 3 | AI35: 2 | AJ35: 3 | AK35: 1 | AL35: 3 | AM35: 1 | AN35: 3 | AO35: 1 | AP35: 8 | AQ35: 4 | AR35: 4 | AS35: 5 | AT35: 4 | AU35: 4 | AV35: 4 | AW35: 6 | AX35: 9 | AY35: 6 | AZ35: 3 | BA35: 6 | BB35: 6 | BC35: 5 | BD35: 4 | BE35: 8 | BF35: 8 | BG35: 5 | BH35: 7 | BI35: 5 | BJ35: 5 | BK35: 6 | BL35: 3 | BM35: 3 | BN35: 6 | BO35: 1 | BP35: 4 | BQ35: 10
B36: Ashley Nicholls | C36: 16 | D36: 13 | E36: 61 | F36: England | G36: Brixham | H36: £1,232 | I36: ST | J36: 36.1 | K36: 62.96 | L36: 20 | M36: 1 | N36: 1 | O36: 1 | P36: 2 | Q36: 1 | R36: 1 | S36: 1 | T36: 1 | U36: 10 | V36: 10 | W36: £2 | X36: 9 | Y36: 9 | Z36: 12 | AA36: 11 | AB36: 20 | AC36: 4 | AD36: 1 | AE36: 1 | AF36: 3 | AG36: 3 | AH36: 1 | AI36: 4 | AJ36: 1 | AK36: 1 | AL36: 1 | AM36: 1 | AN36: 4 | AO36: 1 | AP36: 8 | AQ36: 5 | AR36: 7 | AS36: 7 | AT36: 2 | AU36: 4 | AV36: 13 | AW36: 11 | AX36: 10 | AY36: 6 | AZ36: 2 | BA36: 4 | BB36: 2 | BC36: 3 | BD36: 1 | BE36: 2 | BF36: 8 | BG36: 13 | BH36: 5 | BI36: 3 | BJ36: 4 | BK36: 2 | BL36: 2 | BM36: 1 | BN36: 1 | BO36: 6 | BP36: 1 | BQ36: 10
B37: Erdal Peker | C37: 16 | D37: 43 | E37: 98 | F37: England,Turkey | G37: Brixham | H37: £2,038 | I37: AM R | J37: 38.43 | K37: 58.91 | L37: 1 | M37: 1 | N37: 1 | O37: 20 | P37: 1 | Q37: 1 | R37: 1 | S37: 1 | T37: 1 | U37: 14 | V37: 12 | W37: £11 | X37: 4 | Y37: 10 | Z37: 13 | AA37: 13 | AB37: 20 | AC37: 6 | AD37: 1 | AE37: 3 | AF37: 3 | AG37: 2 | AH37: 2 | AI37: 3 | AJ37: 3 | AK37: 1 | AL37: 1 | AM37: 1 | AN37: 2 | AO37: 1 | AP37: 9 | AQ37: 4 | AR37: 8 | AS37: 4 | AT37: 3 | AU37: 3 | AV37: 8 | AW37: 11 | AX37: 6 | AY37: 5 | AZ37: 1 | BA37: 2 | BB37: 6 | BC37: 6 | BD37: 3 | BE37: 6 | BF37: 5 | BG37: 7 | BH37: 13 | BI37: 1 | BJ37: 1 | BK37: 2 | BL37: 3 | BM37: 1 | BN37: 7 | BO37: 1 | BP37: 1 | BQ37: 10
B38: Paul Jarvis | C38: 16 | D38: 58 | E38: 86 | F38: Wales,England | G38: Brixham | H38: £2,085 | I38: M/AM RL | J38: 42.69 | K38: 56.59 | L38: 1 | M38: 16 | N38: 1 | O38: 1 | P38: 1 | Q38: 1 | R38: 1 | S38: 1 | T38: 1 | U38: 11 | V38: 14 | W38: £9 | X38: 4 | Y38: 20 | Z38: 7 | AA38: 13 | AB38: 8 | AC38: 11 | AD38: 5 | AE38: 2 | AF38: 3 | AG38: 1 | AH38: 2 | AI38: 3 | AJ38: 3 | AK38: 1 | AL38: 3 | AM38: 2 | AN38: 1 | AO38: 2 | AP38: 12 | AQ38: 6 | AR38: 8 | AS38: 6 | AT38: 4 | AU38: 5 | AV38: 4 | AW38: 8 | AX38: 6 | AY38: 7 | AZ38: 2 | BA38: 10 | BB38: 5 | BC38: 15 | BD38: 6 | BE38: 8 | BF38: 10 | BG38: 6 | BH38: 6 | BI38: 11 | BJ38: 1 | BK38: 4 | BL38: 4 | BM38: 2 | BN38: 5 | BO38: 1 | BP38: 4 | BQ38: 8
B39: Jordan Tait | C39: 16 | D39: 37 | E39: 85 | F39: England | G39: Brixham | H39: £1,403 | I39: D L | J39: 36.26 | K39: 56.26 | L39: 1 | M39: 2 | N39: 1 | O39: 1 | P39: 1 | Q39: 20 | R39: 1 | S39: 6 | T39: 1 | U39: 11 | V39: 13 | W39: £4 | X39: 6 | Y39: 20 | Z39: 8 | AA39: 12 | AB39: 9 | AC39: 9 | AD39: 4 | AE39: 3 | AF39: 3 | AG39: 3 | AH39: 2 | AI39: 2 | AJ39: 2 | AK39: 3 | AL39: 1 | AM39: 1 | AN39: 3 | AO39: 3 | AP39: 7 | AQ39: 3 | AR39: 15 | AS39: 4 | AT39: 4 | AU39: 9 | AV39: 9 | AW39: 9 | AX39: 10 | AY39: 5 | AZ39: 6 | BA39: 9 | BB39: 3 | BC39: 13 | BD39: 2 | BE39: 6 | BF39: 4 | BG39: 3 | BH39: 4 | BI39: 2 | BJ39: 3 | BK39: 1 | BL39: 1 | BM39: 7 | BN39: 6 | BO39: 2 | BP39: 5 | BQ39: 9

Sheet Paste Full
A1: Number | B1: Inf | C1: Name | D1: Positions | E1: Nationalities | F1: CA | G1: PA | H1: Age | I1: Current Rep. | J1: Asking Price | K1: Condition (%) | L1: Banned | M1: Is Injured | N1: Fatigue | O1: Match Sharpness | P1: Consistency | Q1: Dirtiness | R1: Important Matches | S1: Injury Proneness | T1: Versatility | U1: Adaptability | V1: Ambition | W1: Controversy | X1: Loyalty | Y1: Pressure | Z1: Professional | AA1: Sportsmanship | AB1: Temperament | AC1: Acceleration | AD1: Agility | AE1: Balance | AF1: Jumping | AG1: Left Foot | AH1: Natural Fitness | AI1: Pace | AJ1: Right Foot | AK1: Stamina | AL1: Strength | AM1: Aerial Ability | AN1: Command Of Area | AO1: Communication | AP1: Eccentricity | AQ1: Handling | AR1: Kicking | AS1: One On Ones | AT1: Reflexes | AU1: Rushing Out | AV1: Tendency To Punch | AW1: Throwing | AX1: Aggression | AY1: Anticipation | AZ1: Bravery | BA1: Composure | BB1: Concentration | BC1: Decisions | BD1: Determination | BE1: Flair | BF1: Leadership | BG1: Off The Ball | BH1: Positioning | BI1: Teamwork | BJ1: Vision | BK1: Workrate | BL1: Corners | BM1: Crossing | BN1: Dribbling | BO1: Finishing | BP1: First Touch | BQ1: Freekicks | BR1: Heading | BS1: Long Shots | BT1: Longthrows | BU1: Marking | BV1: Passing | BW1: Penalty Taking | BX1: Tackling | BY1: Technique | BZ1: GoalKeeper | CA1: Defender Right | CB1: Defender Center | CC1: Defender Left | CD1: Defensive Midfielder | CE1: Attacking Mid. Right | CF1: Attacking Mid. Center | CG1: Attacking Mid. Left | CH1: Striker | CI1: Club
A2: 29 | C2: Allan Hall | D2: DM/M/AM C | E2: England,Australia | F2: 82 | G2: 146 | H2: 17 | I2: 1175 | J2: $3,320 | K2: 9560 | L2: False | M2: False | N2: 31 | O2: 9900 | P2: 13 | Q2: 8 | R2: 15 | S2: 8 | T2: 9 | U2: 11 | V2: 10 | W2: 7 | X2: 14 | Y2: 17 | Z2: 13 | AA2: 13 | AB2: 14 | AC2: 13 | AD2: 16 | AE2: $11 | AF2: 3 | AG2: 12 | AH2: 13 | AI2: 13 | AJ2: 20 | AK2: 14 | AL2: 5 | AM2: 3 | AN2: 1 | AO2: 2 | AP2: 2 | AQ2: 2 | AR2: 2 | AS2: 1 | AT2: 3 | AU2: 3 | AV2: 4 | AW2: 2 | AX2: 10 | AY2: 8 | AZ2: 13 | BA2: 7 | BB2: 3 | BC2: 10 | BD2: 13 | BE2: 11 | BF2: 1 | BG2: 6 | BH2: 3 | BI2: 7 | BJ2: 12 | BK2: 13 | BL2: 3 | BM2: 8 | BN2: 6 | BO2: 8 | BP2: 9 | BQ2: 3 | BR2: 3 | BS2: 6 | BT2: 2 | BU2: 3 | BV2: 10 | BW2: 6 | BX2: 3 | BY2: 9 | BZ2: 1 | CA2: 1 | CB2: 1 | CC2: 1 | CD2: 20 | CE2: 6 | CF2: 16 | CG2: 1 | CH2: 1
A3: 1 | C3: Ashley Sarahs | D3: GK | E3: Northern Ireland,England | F3: 93 | G3: 146 | H3: 18 | I3: 2095 | J3: $7,788 | K3: 9756 | L3: False | M3: False | N3: -52 | O3: 10000 | P3: 15 | Q3: 9 | R3: 12 | S3: 14 | T3: 12 | U3: 12 | V3: 12 | W3: 7 | X3: 10 | Y3: 11 | Z3: 11 | AA3: 9 | AB3: 8 | AC3: 10 | AD3: 11 | AE3: $9 | AF3: 16 | AG3: 16 | AH3: 7 | AI3: 9 | AJ3: 20 | AK3: 4 | AL3: 7 | AM3: 12 | AN3: 9 | AO3: 11 | AP3: 2 | AQ3: 16 | AR3: 6 | AS3: 12 | AT3: 15 | AU3: 15 | AV3: 5 | AW3: 8 | AX3: 10 | AY3: 14 | AZ3: 7 | BA3: 5 | BB3: 12 | BC3: 13 | BD3: 9 | BE3: 3 | BF3: 6 | BG3: 3 | BH3: 8 | BI3: 11 | BJ3: 2 | BK3: 8 | BL3: 4 | BM3: 1 | BN3: 3 | BO3: 1 | BP3: 6 | BQ3: 5 | BR3: 1 | BS3: 2 | BT3: 2 | BU3: 1 | BV3: 5 | BW3: 1 | BX3: 1 | BY3: 11 | BZ3: 20 | CA3: 1 | CB3: 1 | CC3: 1 | CD3: 1 | CE3: 1 | CF3: 1 | CG3: 1 | CH3: 1
A4: 62 | C4: Aston Daley | D4: M C | E4: England | F4: 76 | G4: 86 | H4: 21 | I4: 3249 | J4: $0 | K4: 10000 | L4: False | M4: False | N4: -283 | O4: 5750 | P4: 18 | Q4: 7 | R4: 8 | S4: 12 | T4: 12 | U4: 11 | V4: 10 | W4: 10 | X4: 10 | Y4: 9 | Z4: 11 | AA4: 10 | AB4: 10 | AC4: 15 | AD4: 11 | AE4: $11 | AF4: 8 | AG4: 9 | AH4: 13 | AI4: 15 | AJ4: 20 | AK4: 12 | AL4: 8 | AM4: 3 | AN4: 2 | AO4: 2 | AP4: 1 | AQ4: 2 | AR4: 2 | AS4: 1 | AT4: 1 | AU4: 3 | AV4: 2 | AW4: 2 | AX4: 12 | AY4: 10 | AZ4: 5 | BA4: 11 | BB4: 7 | BC4: 5 | BD4: 15 | BE4: 7 | BF4: 6 | BG4: 8 | BH4: 8 | BI4: 8 | BJ4: 10 | BK4: 13 | BL4: 6 | BM4: 7 | BN4: 8 | BO4: 6 | BP4: 12 | BQ4: 5 | BR4: 1 | BS4: 9 | BT4: 1 | BU4: 9 | BV4: 9 | BW4: 3 | BX4: 9 | BY4: 13 | BZ4: 1 | CA4: 1 | CB4: 1 | CC4: 1 | CD4: 1 | CE4: 3 | CF4: 1 | CG4: 1 | CH4: 1
A5: 7 | C5: Aydin Webb | D5: DM/M/AM RLC | E5: England | F5: 94 | G5: 135 | H5: 18 | I5: 1589 | J5: $4,251 | K5: 9215 | L5: False | M5: False | N5: 183 | O5: 10000 | P5: 11 | Q5: 14 | R5: 13 | S5: 11 | T5: 12 | U5: 11 | V5: 11 | W5: 6 | X5: 13 | Y5: 11 | Z5: 15 | AA5: 9 | AB5: 8 | AC5: 8 | AD5: 9 | AE5: $9 | AF5: 9 | AG5: 10 | AH5: 14 | AI5: 9 | AJ5: 20 | AK5: 14 | AL5: 9 | AM5: 2 | AN5: 2 | AO5: 3 | AP5: 1 | AQ5: 1 | AR5: 3 | AS5: 1 | AT5: 2 | AU5: 1 | AV5: 1 | AW5: 3 | AX5: 11 | AY5: 7 | AZ5: 9 | BA5: 10 | BB5: 12 | BC5: 13 | BD5: 17 | BE5: 11 | BF5: 10 | BG5: 11 | BH5: 8 | BI5: 14 | BJ5: 13 | BK5: 13 | BL5: 4 | BM5: 7 | BN5: 7 | BO5: 9 | BP5: 15 | BQ5: 5 | BR5: 4 | BS5: 8 | BT5: 3 | BU5: 8 | BV5: 10 | BW5: 4 | BX5: 10 | BY5: 12 | BZ5: 1 | CA5: 1 | CB5: 1 | CC5: 1 | CD5: 20 | CE5: 20 | CF5: 1 | CG5: 16 | CH5: 1
A6: 25 | C6: Daniel Willard | D6: AM L | E6: Northern Ireland,England | F6: 91 | G6: 149 | H6: 17 | I6: 1788 | J6: $5,854 | K6: 9617 | L6: True | M6: False | N6: 67 | O6: 10000 | P6: 9 | Q6: 14 | R6: 15 | S6: 4 | T6: 14 | U6: 11 | V6: 16 | W6: 16 | X6: 12 | Y6: 16 | Z6: 13 | AA6: 4 | AB6: 6 | AC6: 15 | AD6: 16 | AE6: $12 | AF6: 7 | AG6: 20 | AH6: 6 | AI6: 14 | AJ6: 11 | AK6: 14 | AL6: 6 | AM6: 3 | AN6: 1 | AO6: 1 | AP6: 2 | AQ6: 1 | AR6: 1 | AS6: 1 | AT6: 2 | AU6: 3 | AV6: 1 | AW6: 1 | AX6: 7 | AY6: 8 | AZ6: 10 | BA6: 9 | BB6: 5 | BC6: 7 | BD6: 18 | BE6: 12 | BF6: 7 | BG6: 10 | BH6: 4 | BI6: 6 | BJ6: 12 | BK6: 8 | BL6: 5 | BM6: 5 | BN6: 9 | BO6: 10 | BP6: 12 | BQ6: 8 | BR6: 6 | BS6: 5 | BT6: 3 | BU6: 5 | BV6: 10 | BW6: 7 | BX6: 3 | BY6: 11 | BZ6: 1 | CA6: 1 | CB6: 1 | CC6: 1 | CD6: 1 | CE6: 1 | CF6: 10 | CG6: 20 | CH6: 4
A7: 45 | C7: Donell Gordon | D7: M/AM RL | E7: England | F7: 44 | G7: 81 | H7: 22 | I7: 2587 | J7: $0 | K7: 7816 | L7: False | M7: False | N7: -270 | O7: 8400 | P7: 10 | Q7: 12 | R7: 8 | S7: 12 | T7: 8 | U7: 10 | V7: 10 | W7: 9 | X7: 10 | Y7: 10 | Z7: 11 | AA7: 10 | AB7: 10 | AC7: 12 | AD7: 12 | AE7: $2 | AF7: 3 | AG7: 12 | AH7: 8 | AI7: 11 | AJ7: 20 | AK7: 11 | AL7: 1 | AM7: 1 | AN7: 2 | AO7: 3 | AP7: 2 | AQ7: 4 | AR7: 1 | AS7: 1 | AT7: 2 | AU7: 1 | AV7: 2 | AW7: 1 | AX7: 12 | AY7: 6 | AZ7: 3 | BA7: 2 | BB7: 3 | BC7: 7 | BD7: 3 | BE7: 8 | BF7: 9 | BG7: 7 | BH7: 3 | BI7: 5 | BJ7: 3 | BK7: 9 | BL7: 4 | BM7: 9 | BN7: 10 | BO7: 4 | BP7: 10 | BQ7: 3 | BR7: 2 | BS7: 3 | BT7: 3 | BU7: 2 | BV7: 9 | BW7: 1 | BX7: 3 | BY7: 5 | BZ7: 1 | CA7: 1 | CB7: 1 | CC7: 1 | CD7: 1 | CE7: 20 | CF7: 2 | CG7: 16 | CH7: 1
A8: 28 | C8: Fletcher Poole | D8: M/AM RLC | E8: England | F8: 54 | G8: 85 | H8: 20 | I8: 2663 | J8: $0 | K8: 7919 | L8: False | M8: False | N8: -156 | O8: 9200 | P8: 5 | Q8: 6 | R8: 5 | S8: 12 | T8: 11 | U8: 10 | V8: 10 | W8: 10 | X8: 10 | Y8: 10 | Z8: 10 | AA8: 10 | AB8: 10 | AC8: 13 | AD8: 10 | AE8: $13 | AF8: 9 | AG8: 7 | AH8: 10 | AI8: 13 | AJ8: 20 | AK8: 9 | AL8: 4 | AM8: 1 | AN8: 3 | AO8: 4 | AP8: 3 | AQ8: 3 | AR8: 3 | AS8: 3 | AT8: 3 | AU8: 1 | AV8: 2 | AW8: 3 | AX8: 9 | AY8: 5 | AZ8: 6 | BA8: 8 | BB8: 4 | BC8: 4 | BD8: 9 | BE8: 11 | BF8: 7 | BG8: 7 | BH8: 3 | BI8: 11 | BJ8: 11 | BK8: 11 | BL8: 3 | BM8: 8 | BN8: 4 | BO8: 6 | BP8: 10 | BQ8: 3 | BR8: 3 | BS8: 4 | BT8: 3 | BU8: 2 | BV8: 6 | BW8: 1 | BX8: 4 | BY8: 11 | BZ8: 1 | CA8: 2 | CB8: 1 | CC8: 1 | CD8: 1 | CE8: 18 | CF8: 15 | CG8: 20 | CH8: 1
A9: 24 | C9: Gastón Ramírez | D9: AM/ST L | E9: Argentina,England | F9: 83 | G9: 140 | H9: 16 | I9: 1295 | J9: $3,577 | K9: 8201 | L9: False | M9: False | N9: 98 | O9: 8400 | P9: 11 | Q9: 8 | R9: 11 | S9: 2 | T9: 10 | U9: 7 | V9: 11 | W9: 8 | X9: 13 | Y9: 12 | Z9: 15 | AA9: 12 | AB9: 18 | AC9: 14 | AD9: 11 | AE9: $13 | AF9: 7 | AG9: 16 | AH9: 11 | AI9: 10 | AJ9: 20 | AK9: 8 | AL9: 7 | AM9: 1 | AN9: 1 | AO9: 4 | AP9: 1 | AQ9: 1 | AR9: 3 | AS9: 1 | AT9: 2 | AU9: 2 | AV9: 1 | AW9: 1 | AX9: 9 | AY9: 9 | AZ9: 5 | BA9: 7 | BB9: 5 | BC9: 6 | BD9: 14 | BE9: 15 | BF9: 12 | BG9: 11 | BH9: 6 | BI9: 8 | BJ9: 8 | BK9: 5 | BL9: 6 | BM9: 10 | BN9: 9 | BO9: 8 | BP9: 11 | BQ9: 5 | BR9: 14 | BS9: 9 | BT9: 3 | BU9: 2 | BV9: 10 | BW9: 8 | BX9: 4 | BY9: 14 | BZ9: 1 | CA9: 1 | CB9: 1 | CC9: 1 | CD9: 1 | CE9: 1 | CF9: 1 | CG9: 16 | CH9: 20
A10: 12 | C10: Gustavo Xavier | D10: D L | E10: Brazil | F10: 84 | G10: 107 | H10: 23 | I10: 4561 | J10: $115,348 | K10: 9646 | L10: False | M10: False | N10: -58 | O10: 9400 | P10: 11 | Q10: 11 | R10: 14 | S10: 9 | T10: 16 | U10: 10 | V10: 10 | W10: 10 | X10: 10 | Y10: 10 | Z10: 10 | AA10: 10 | AB10: 11 | AC10: 13 | AD10: 13 | AE10: $7 | AF10: 6 | AG10: 20 | AH10: 14 | AI10: 12 | AJ10: 5 | AK10: 14 | AL10: 8 | AM10: 3 | AN10: 1 | AO10: 1 | AP10: 3 | AQ10: 1 | AR10: 3 | AS10: 2 | AT10: 1 | AU10: 2 | AV10: 4 | AW10: 1 | AX10: 14 | AY10: 13 | AZ10: 10 | BA10: 9 | BB10: 12 | BC10: 12 | BD10: 9 | BE10: 9 | BF10: 4 | BG10: 10 | BH10: 12 | BI10: 11 | BJ10: 10 | BK10: 11 | BL10: 4 | BM10: 9 | BN10: 10 | BO10: 6 | BP10: 10 | BQ10: 3 | BR10: 8 | BS10: 3 | BT10: 11 | BU10: 8 | BV10: 10 | BW10: 5 | BX10: 7 | BY10: 10 | BZ10: 1 | CA10: 11 | CB10: 1 | CC10: 20 | CD10: 3 | CE10: 1 | CF10: 1 | CG10: 1 | CH10: 1
A11: 8 | C11: Hisashi Roddy | D11: D/WB RL | E11: England | F11: 101 | G11: 158 | H11: 17 | I11: 2573 | J11: $18,092 | K11: 9287 | L11: False | M11: False | N11: 138 | O11: 10000 | P11: 9 | Q11: 10 | R11: 15 | S11: 9 | T11: 10 | U11: 11 | V11: 10 | W11: 16 | X11: 10 | Y11: 17 | Z11: 11 | AA11: 5 | AB11: 7 | AC11: 13 | AD11: 12 | AE11: $15 | AF11: 12 | AG11: 15 | AH11: 18 | AI11: 11 | AJ11: 20 | AK11: 15 | AL11: 8 | AM11: 3 | AN11: 4 | AO11: 1 | AP11: 3 | AQ11: 1 | AR11: 1 | AS11: 1 | AT11: 2 | AU11: 1 | AV11: 3 | AW11: 1 | AX11: 14 | AY11: 12 | AZ11: 15 | BA11: 6 | BB11: 11 | BC11: 10 | BD11: 11 | BE11: 6 | BF11: 8 | BG11: 10 | BH11: 11 | BI11: 9 | BJ11: 11 | BK11: 14 | BL11: 2 | BM11: 7 | BN11: 6 | BO11: 2 | BP11: 9 | BQ11: 1 | BR11: 4 | BS11: 3 | BT11: 4 | BU11: 10 | BV11: 8 | BW11: 4 | BX11: 14 | BY11: 14 | BZ11: 1 | CA11: 20 | CB11: 1 | CC11: 16 | CD11: 1 | CE11: 1 | CF11: 1 | CG11: 1 | CH11: 1
A12: 27 | C12: Jamie McMurdo | D12: M C | E12: Scotland | F12: 69 | G12: 82 | H12: 20 | I12: 3250 | J12: $0 | K12: 10000 | L12: False | M12: False | N12: -224 | O12: 5500 | P12: 7 | Q12: 9 | R12: 7 | S12: 14 | T12: 13 | U12: 10 | V12: 10 | W12: 9 | X12: 11 | Y12: 9 | Z12: 11 | AA12: 10 | AB12: 11 | AC12: 14 | AD12: 11 | AE12: $14 | AF12: 11 | AG12: 8 | AH12: 8 | AI12: 11 | AJ12: 20 | AK12: 11 | AL12: 5 | AM12: 3 | AN12: 1 | AO12: 2 | AP12: 1 | AQ12: 1 | AR12: 2 | AS12: 4 | AT12: 2 | AU12: 3 | AV12: 2 | AW12: 3 | AX12: 12 | AY12: 10 | AZ12: 6 | BA12: 8 | BB12: 6 | BC12: 7 | BD12: 7 | BE12: 9 | BF12: 12 | BG12: 6 | BH12: 4 | BI12: 13 | BJ12: 9 | BK12: 13 | BL12: 5 | BM12: 11 | BN12: 8 | BO12: 5 | BP12: 11 | BQ12: 5 | BR12: 6 | BS12: 7 | BT12: 5 | BU12: 10 | BV12: 14 | BW12: 1 | BX12: 8 | BY12: 10 | BZ12: 1 | CA12: 1 | CB12: 1 | CC12: 1 | CD12: 1 | CE12: 12 | CF12: 2 | CG12: 1 | CH12: 1
A13: 26 | C13: Jayden Cumberbatch | D13: D LC | E13: Jamaica,England | F13: 80 | G13: 144 | H13: 17 | I13: 1616 | J13: $4,119 | K13: 9232 | L13: False | M13: False | N13: 76 | O13: 9900 | P13: 8 | Q13: 8 | R13: 15 | S13: 6 | T13: 12 | U13: 15 | V13: 5 | W13: 3 | X13: 14 | Y13: 16 | Z13: 7 | AA13: 14 | AB13: 17 | AC13: 9 | AD13: 6 | AE13: $10 | AF13: 17 | AG13: 12 | AH13: 13 | AI13: 8 | AJ13: 20 | AK13: 6 | AL13: 14 | AM13: 2 | AN13: 4 | AO13: 1 | AP13: 2 | AQ13: 3 | AR13: 2 | AS13: 3 | AT13: 2 | AU13: 2 | AV13: 1 | AW13: 1 | AX13: 19 | AY13: 11 | AZ13: 8 | BA13: 3 | BB13: 11 | BC13: 10 | BD13: 14 | BE13: 4 | BF13: 14 | BG13: 4 | BH13: 9 | BI13: 6 | BJ13: 8 | BK13: 7 | BL13: 3 | BM13: 4 | BN13: 4 | BO13: 1 | BP13: 6 | BQ13: 4 | BR13: 13 | BS13: 1 | BT13: 1 | BU13: 14 | BV13: 5 | BW13: 3 | BX13: 12 | BY13: 12 | BZ13: 1 | CA13: 1 | CB13: 20 | CC13: 16 | CD13: 1 | CE13: 1 | CF13: 1 | CG13: 1 | CH13: 1
... A19: 14 | C19: Mateusz Widz | D19: AM/ST R | E19: England,Poland | F19: 91 | G19: 139 | H19: 17 | I19: 1630 | J19: $5,318 | K19: 9521 | L19: False | M19: False | N19: 73 | O19: 10000 | P19: 13 | Q19: 11 | R19: 12 | S19: 11 | T19: 10 | U19: 10 | V19: 13 | W19: 4 | X19: 17 | Y19: 13 | Z19: 15 | AA19: 18 | AB19: 18 | AC19: 12 | AD19: 13 | AE19: $13 | AF19: 12 | AG19: 9 | AH19: 11 | AI19: 12 | AJ19: 20 | AK19: 9 | AL19: 8 | AM19: 2 | AN19: 3 | AO19: 2 | AP19: 1 | AQ19: 1 | AR19: 1 | AS19: 2 | AT19: 2 | AU19: 3 | AV19: 1 | AW19: 2 | AX19: 12 | AY19: 11 | AZ19: 12 | BA19: 10 | BB19: 5 | BC19: 11 | BD19: 13 | BE19: 15 | BF19: 9 | BG19: 12 | BH19: 6 | BI19: 14 | BJ19: 6 | BK19: 11 | BL19: 7 | BM19: 11 | BN19: 9 | BO19: 15 | BP19: 11 | BQ19: 6 | BR19: 5 | BS19: 5 | BT19: 1 | BU19: 7 | BV19: 11 | BW19: 7 | BX19: 5 | BY19: 14 | BZ19: 1 | CA19: 1 | CB19: 1 | CC19: 1 | CD19: 1 | CE19: 20 | CF19: 5 | CG19: 1 | CH19: 16
A20: 49 | C20: Mattia Mendolia | D20: M/AM C | E20: Italy | F20: 85 | G20: 101 | H20: 20 | I20: 4022 | J20: $126,078 | K20: 9481 | L20: False | M20: False | N20: -88 | O20: 9300 | P20: 10 | Q20: 11 | R20: 9 | S20: 15 | T20: 9 | U20: 10 | V20: 10 | W20: 10 | X20: 11 | Y20: 10 | Z20: 13 | AA20: 10 | AB20: 10 | AC20: 9 | AD20: 12 | AE20: $11 | AF20: 7 | AG20: 20 | AH20: 17 | AI20: 12 | AJ20: 5 | AK20: 12 | AL20: 8 | AM20: 2 | AN20: 3 | AO20: 1 | AP20: 3 | AQ20: 2 | AR20: 3 | AS20: 1 | AT20: 3 | AU20: 1 | AV20: 2 | AW20: 1 | AX20: 14 | AY20: 10 | AZ20: 7 | BA20: 11 | BB20: 7 | BC20: 12 | BD20: 16 | BE20: 14 | BF20: 3 | BG20: 12 | BH20: 10 | BI20: 9 | BJ20: 10 | BK20: 15 | BL20: 8 | BM20: 9 | BN20: 10 | BO20: 10 | BP20: 12 | BQ20: 7 | BR20: 6 | BS20: 12 | BT20: 7 | BU20: 6 | BV20: 13 | BW20: 6 | BX20: 9 | BY20: 15 | BZ20: 1 | CA20: 1 | CB20: 1 | CC20: 1 | CD20: 1 | CE20: 1 | CF20: 20 | CG20: 1 | CH20: 1 | CI20: Brixham
A21: 2 | C21: Nesbert Ncube | D21: D R | E21: Zimbabwe,England | F21: 71 | G21: 139 | H21: 16 | I21: 1204 | J21: $2,988 | K21: 9615 | L21: False | M21: False | N21: 74 | O21: 9700 | P21: 6 | Q21: 9 | R21: 9 | S21: 7 | T21: 11 | U21: 13 | V21: 19 | W21: 9 | X21: 13 | Y21: 4 | Z21: 10 | AA21: 12 | AB21: 11 | AC21: 12 | AD21: 10 | AE21: $7 | AF21: 6 | AG21: 8 | AH21: 7 | AI21: 10 | AJ21: 20 | AK21: 14 | AL21: 7 | AM21: 3 | AN21: 3 | AO21: 2 | AP21: 1 | AQ21: 2 | AR21: 1 | AS21: 3 | AT21: 1 | AU21: 1 | AV21: 2 | AW21: 3 | AX21: 10 | AY21: 9 | AZ21: 18 | BA21: 2 | BB21: 8 | BC21: 14 | BD21: 19 | BE21: 4 | BF21: 8 | BG21: 7 | BH21: 7 | BI21: 15 | BJ21: 5 | BK21: 13 | BL21: 4 | BM21: 11 | BN21: 6 | BO21: 3 | BP21: 6 | BQ21: 1 | BR21: 5 | BS21: 2 | BT21: 5 | BU21: 9 | BV21: 8 | BW21: 2 | BX21: 11 | BY21: 5 | BZ21: 1 | CA21: 20 | CB21: 1 | CC21: 9 | CD21: 1 | CE21: 1 | CF21: 1 | CG21: 1 | CH21: 1
A22: 63 | C22: Ollie Harrison | D22: DM/M C | E22: England | F22: 97 | G22: 124 | H22: 20 | I22: 4049 | J22: $813,173 | K22: 9333 | L22: False | M22: False | N22: -49 | O22: 9300 | P22: 19 | Q22: 5 | R22: 16 | S22: 7 | T22: 4 | U22: 11 | V22: 10 | W22: 9 | X22: 11 | Y22: 11 | Z22: 10 | AA22: 11 | AB22: 11 | AC22: 13 | AD22: 10 | AE22: $15 | AF22: 13 | AG22: 10 | AH22: 8 | AI22: 12 | AJ22: 20 | AK22: 10 | AL22: 13 | AM22: 1 | AN22: 1 | AO22: 3 | AP22: 1 | AQ22: 2 | AR22: 3 | AS22: 1 | AT22: 2 | AU22: 1 | AV22: 2 | AW22: 3 | AX22: 10 | AY22: 13 | AZ22: 10 | BA22: 11 | BB22: 10 | BC22: 11 | BD22: 12 | BE22: 5 | BF22: 13 | BG22: 10 | BH22: 13 | BI22: 12 | BJ22: 12 | BK22: 13 | BL22: 6 | BM22: 5 | BN22: 8 | BO22: 6 | BP22: 11 | BQ22: 8 | BR22: 8 | BS22: 5 | BT22: 6 | BU22: 10 | BV22: 12 | BW22: 3 | BX22: 10 | BY22: 12 | BZ22: 1 | CA22: 1 | CB22: 1 | CC22: 1 | CD22: 18 | CE22: 1 | CF22: 12 | CG22: 1 | CH22: 1 | CI22: Brixham
A23: 16 | C23: Paul Stroud | D23: AM/ST RC | E23: England | F23: 103 | G23: 156 | H23: 18 | I23: 2806 | J23: $32,663 | K23: 9660 | L23: False | M23: False | N23: 92 | O23: 10000 | P23: 9 | Q23: 8 | R23: 15 | S23: 4 | T23: 7 | U23: 11 | V23: 15 | W23: 5 | X23: 18 | Y23: 18 | Z23: 19 | AA23: 19 | AB23: 18 | AC23: 15 | AD23: 12 | AE23: $16 | AF23: 8 | AG23: 11 | AH23: 17 | AI23: 13 | AJ23: 20 | AK23: 14 | AL23: 7 | AM23: 3 | AN23: 4 | AO23: 1 | AP23: 2 | AQ23: 2 | AR23: 3 | AS23: 3 | AT23: 1 | AU23: 3 | AV23: 2 | AW23: 2 | AX23: 6 | AY23: 11 | AZ23: 8 | BA23: 8 | BB23: 5 | BC23: 9 | BD23: 12 | BE23: 14 | BF23: 12 | BG23: 11 | BH23: 4 | BI23: 13 | BJ23: 12 | BK23: 8 | BL23: 5 | BM23: 6 | BN23: 14 | BO23: 6 | BP23: 13 | BQ23: 4 | BR23: 6 | BS23: 8 | BT23: 2 | BU23: 6 | BV23: 11 | BW23: 7 | BX23: 4 | BY23: 15 | BZ23: 1 | CA23: 1 | CB23: 1 | CC23: 1 | CD23: 1 | CE23: 16 | CF23: 20 | CG23: 1 | CH23: 20
A24: 9 | C24: Scot Little | D24: AM/ST L | E24: Scotland,England | F24: 90 | G24: 163 | H24: 18 | I24: 2247 | J24: $4,552 | K24: 10000 | L24: False | M24: False | N24: -124 | O24: 8616 | P24: 15 | Q24: 14 | R24: 9 | S24: 6 | T24: 10 | U24: 8 | V24: 3 | W24: 8 | X24: 11 | Y24: 9 | Z24: 10 | AA24: 11 | AB24: 13 | AC24: 11 | AD24: 12 | AE24: $14 | AF24: 5 | AG24: 20 | AH24: 12 | AI24: 12 | AJ24: 13 | AK24: 11 | AL24: 4 | AM24: 1 | AN24: 1 | AO24: 3 | AP24: 3 | AQ24: 2 | AR24: 2 | AS24: 3 | AT24: 3 | AU24: 1 | AV24: 1 | AW24: 2 | AX24: 11 | AY24: 11 | AZ24: 5 | BA24: 12 | BB24: 5 | BC24: 11 | BD24: 3 | BE24: 13 | BF24: 6 | BG24: 13 | BH24: 3 | BI24: 15 | BJ24: 8 | BK24: 15 | BL24: 8 | BM24: 11 | BN24: 10 | BO24: 14 | BP24: 14 | BQ24: 4 | BR24: 8 | BS24: 5 | BT24: 2 | BU24: 4 | BV24: 9 | BW24: 6 | BX24: 1 | BY24: 14 | BZ24: 1 | CA24: 1 | CB24: 1 | CC24: 1 | CD24: 1 | CE24: 9 | CF24: 1 | CG24: 16 | CH24: 20
A25: 33 | C25: Taye Weir | D25: D/WB/M L | E25: England | F25: 55 | G25: 90 | H25: 22 | I25: 3230 | J25: $0 | K25: 7146 | L25: False | M25: False | N25: -151 | O25: 8100 | P25: 6 | Q25: 5 | R25: 10 | S25: 9 | T25: 13 | U25: 11 | V25: 10 | W25: 9 | X25: 10 | Y25: 10 | Z25: 11 | AA25: 11 | AB25: 10 | AC25: 14 | AD25: 12 | AE25: $5 | AF25: 9 | AG25: 20 | AH25: 11 | AI25: 12 | AJ25: 9 | AK25: 9 | AL25: 5 | AM25: 3 | AN25: 2 | AO25: 1 | AP25: 2 | AQ25: 1 | AR25: 3 | AS25: 1 | AT25: 1 | AU25: 3 | AV25: 3 | AW25: 2 | AX25: 10 | AY25: 9 | AZ25: 5 | BA25: 6 | BB25: 11 | BC25: 8 | BD25: 12 | BE25: 5 | BF25: 13 | BG25: 6 | BH25: 7 | BI25: 6 | BJ25: 6 | BK25: 7 | BL25: 4 | BM25: 8 | BN25: 6 | BO25: 3 | BP25: 10 | BQ25: 3 | BR25: 4 | BS25: 4 | BT25: 3 | BU25: 9 | BV25: 5 | BW25: 1 | BX25: 10 | BY25: 7 | BZ25: 1 | CA25: 1 | CB25: 1 | CC25: 20 | CD25: 4 | CE25: 1 | CF25: 1 | CG25: 1 | CH25: 1
A26: 6 | C26: Will Hancox | D26: M/AM R | E26: England | F26: 40 | G26: 50 | H26: 30 | I26: 2559 | J26: $0 | K26: 10000 | L26: False | M26: False | N26: -500 | O26: 6000 | P26: 20 | Q26: 1 | R26: 20 | S26: 1 | T26: 20 | U26: 20 | V26: 20 | W26: 1 | X26: 20 | Y26: 20 | Z26: 20 | AA26: 20 | AB26: 20 | AC26: 12 | AD26: 9 | AE26: $5 | AF26: 8 | AG26: 9 | AH26: 9 | AI26: 10 | AJ26: 20 | AK26: 12 | AL26: 4 | AM26: 3 | AN26: 1 | AO26: 3 | AP26: 3 | AQ26: 3 | AR26: 4 | AS26: 3 | AT26: 2 | AU26: 3 | AV26: 2 | AW26: 3 | AX26: 13 | AY26: 8 | AZ26: 2 | BA26: 6 | BB26: 3 | BC26: 8 | BD26: 12 | BE26: 6 | BF26: 13 | BG26: 5 | BH26: 3 | BI26: 6 | BJ26: 4 | BK26: 11 | BL26: 4 | BM26: 10 | BN26: 5 | BO26: 4 | BP26: 10 | BQ26: 4 | BR26: 4 | BS26: 2 | BT26: 3 | BU26: 4 | BV26: 7 | BW26: 1 | BX26: 1 | BY26: 6 | BZ26: 1 | CA26: 1 | CB26: 1 | CC26: 1 | CD26: 3 | CE26: 18 | CF26: 2 | CG26: 1 | CH26: 1
A27: 4 | C27: Zach Awe | D27: D/DM C | E27: England,Nigeria,Saint Lucia | F27: 85 | G27: 121 | H27: 23 | I27: 4681 | J27: $326,706 | K27: 9765 | L27: False | M27: False | N27: 20 | O27: 10000 | P27: 8 | Q27: 8 | R27: 7 | S27: 7 | T27: 10 | U27: 13 | V27: 12 | W27: 6 | X27: 10 | Y27: 9 | Z27: 15 | AA27: 13 | AB27: 13 | AC27: 12 | AD27: 11 | AE27: $11 | AF27: 14 | AG27: 10 | AH27: 10 | AI27: 11 | AJ27: 20 | AK27: 11 | AL27: 13 | AM27: 3 | AN27: 2 | AO27: 3 | AP27: 2 | AQ27: 1 | AR27: 2 | AS27: 2 | AT27: 2 | AU27: 2 | AV27: 1 | AW27: 3 | AX27: 11 | AY27: 12 | AZ27: 12 | BA27: 10 | BB27: 8 | BC27: 8 | BD27: 12 | BE27: 7 | BF27: 7 | BG27: 7 | BH27: 11 | BI27: 10 | BJ27: 10 | BK27: 11 | BL27: 1 | BM27: 4 | BN27: 9 | BO27: 4 | BP27: 10 | BQ27: 4 | BR27: 11 | BS27: 5 | BT27: 2 | BU27: 9 | BV27: 9 | BW27: 4 | BX27: 11 | BY27: 11 | BZ27: 1 | CA27: 1 | CB27: 20 | CC27: 1 | CD27: 16 | CE27: 1 | CF27: 1 | CG27: 1 | CH27: 1
A28: 20 | C28: Abdelaziz El Hariri | D28: GK | E28: Morocco,England | F28: 65 | G28: 140 | H28: 16 | I28: 1130 | J28: $1,818 | K28: 9770 | L28: False | M28: False | N28: 93 | O28: 9200 | P28: 6 | Q28: 12 | R28: 5 | S28: 13 | T28: 10 | U28: 12 | V28: 17 | W28: 15 | X28: 17 | Y28: 16 | Z28: 17 | AA28: 16 | AB28: 16 | AC28: 6 | AD28: 10 | AE28: $5 | AF28: 13 | AG28: 11 | AH28: 11 | AI28: 7 | AJ28: 20 | AK28: 6 | AL28: 8 | AM28: 10 | AN28: 9 | AO28: 8 | AP28: 8 | AQ28: 13 | AR28: 9 | AS28: 10 | AT28: 13 | AU28: 14 | AV28: 7 | AW28: 7 | AX28: 12 | AY28: 5 | AZ28: 6 | BA28: 6 | BB28: 10 | BC28: 12 | BD28: 11 | BE28: 2 | BF28: 4 | BG28: 3 | BH28: 11 | BI28: 2 | BJ28: 3 | BK28: 3 | BL28: 3 | BM28: 3 | BN28: 2 | BO28: 3 | BP28: 2 | BQ28: 4 | BR28: 1 | BS28: 3 | BT28: 3 | BU28: 2 | BV28: 5 | BW28: 2 | BX28: 3 | BY28: 6 | BZ28: 20 | CA28: 1 | CB28: 1 | CC28: 1 | CD28: 1 | CE28: 1 | CF28: 1 | CG28: 1 | CH28: 1
A29: 15 | C29: Aiden Warne | D29: ST | E29: England | F29: 40 | G29: 77 | H29: 20 | I29: 1226 | J29: $0 | K29: 10000 | L29: False | M29: False | N29: -225 | O29: 6300 | P29: 14 | Q29: 15 | R29: 7 | S29: 11 | T29: 8 | U29: 10 | V29: 10 | W29: 10 | X29: 10 | Y29: 10 | Z29: 10 | AA29: 10 | AB29: 10 | AC29: 11 | AD29: 10 | AE29: $6 | AF29: 3 | AG29: 11 | AH29: 16 | AI29: 10 | AJ29: 20 | AK29: 10 | AL29: 4 | AM29: 1 | AN29: 2 | AO29: 2 | AP29: 3 | AQ29: 1 | AR29: 2 | AS29: 1 | AT29: 2 | AU29: 3 | AV29: 4 | AW29: 3 | AX29: 12 | AY29: 6 | AZ29: 4 | BA29: 7 | BB29: 2 | BC29: 9 | BD29: 15 | BE29: 6 | BF29: 4 | BG29: 10 | BH29: 2 | BI29: 2 | BJ29: 1 | BK29: 4 | BL29: 2 | BM29: 3 | BN29: 12 | BO29: 12 | BP29: 9 | BQ29: 3 | BR29: 12 | BS29: 2 | BT29: 1 | BU29: 1 | BV29: 1 | BW29: 2 | BX29: 1 | BY29: 4 | BZ29: 1 | CA29: 1 | CB29: 1 | CC29: 1 | CD29: 1 | CE29: 1 | CF29: 1 | CG29: 1 | CH29: 20
A30: 53 | C30: Alessandro Trapasso | D30: D/WB R | E30: England | F30: 42 | G30: 80 | H30: 20 | I30: 435 | J30: $0 | K30: 10000 | L30: False | M30: False | N30: -224 | O30: 6050 | P30: 7 | Q30: 11 | R30: 14 | S30: 13 | T30: 10 | U30: 10 | V30: 10 | W30: 10 | X30: 10 | Y30: 10 | Z30: 10 | AA30: 10 | AB30: 10 | AC30: 11 | AD30: 10 | AE30: $7 | AF30: 9 | AG30: 10 | AH30: 11 | AI30: 12 | AJ30: 20 | AK30: 5 | AL30: 5 | AM30: 1 | AN30: 4 | AO30: 1 | AP30: 4 | AQ30: 2 | AR30: 3 | AS30: 3 | AT30: 3 | AU30: 3 | AV30: 2 | AW30: 3 | AX30: 5 | AY30: 6 | AZ30: 7 | BA30: 6 | BB30: 6 | BC30: 11 | BD30: 7 | BE30: 5 | BF30: 11 | BG30: 5 | BH30: 7 | BI30: 7 | BJ30: 6 | BK30: 7 | BL30: 4 | BM30: 10 | BN30: 2 | BO30: 3 | BP30: 9 | BQ30: 2 | BR30: 6 | BS30: 1 | BT30: 4 | BU30: 8 | BV30: 6 | BW30: 2 | BX30: 12 | BY30: 6 | BZ30: 1 | CA30: 20 | CB30: 1 | CC30: 1 | CD30: 1 | CE30: 1 | CF30: 1 | CG30: 1 | CH30: 1
A31: -1 | C31: Amani Bowlin | D31: D C | E31: England | F31: 33 | G31: 81 | H31: 20 | I31: 612 | J31: $0 | K31: 10000 | L31: False | M31: False | N31: -224 | O31: 5850 | P31: 10 | Q31: 11 | R31: 10 | S31: 12 | T31: 6 | U31: 10 | V31: 10 | W31: 10 | X31: 11 | Y31: 10 | Z31: 10 | AA31: 10 | AB31: 10 | AC31: 13 | AD31: 11 | AE31: $15 | AF31: 7 | AG31: 11 | AH31: 7 | AI31: 10 | AJ31: 20 | AK31: 6 | AL31: 6 | AM31: 2 | AN31: 2 | AO31: 3 | AP31: 2 | AQ31: 2 | AR31: 2 | AS31: 3 | AT31: 1 | AU31: 1 | AV31: 1 | AW31: 2 | AX31: 10 | AY31: 12 | AZ31: 7 | BA31: 4 | BB31: 6 | BC31: 7 | BD31: 13 | BE31: 6 | BF31: 11 | BG31: 7 | BH31: 4 | BI31: 7 | BJ31: 5 | BK31: 7 | BL31: 3 | BM31: 5 | BN31: 5 | BO31: 1 | BP31: 5 | BQ31: 1 | BR31: 7 | BS31: 1 | BT31: 1 | BU31: 6 | BV31: 7 | BW31: 1 | BX31: 7 | BY31: 8 | BZ31: 1 | CA31: 1 | CB31: 20 | CC31: 1 | CD31: 1 | CE31: 1 | CF31: 1 | CG31: 1 | CH31: 1
A32: -1 | C32: Ben Scothern | D32: D C | E32: England | F32: 35 | G32: 90 | H32: 19 | I32: 265 | J32: $0 | K32: 10000 | L32: False | M32: False | N32: -222 | O32: 6100 | P32: 7 | Q32: 5 | R32: 9 | S32: 10 | T32: 9 | U32: 10 | V32: 10 | W32: 10 | X32: 10 | Y32: 10 | Z32: 11 | AA32: 10 | AB32: 10 | AC32: 10 | AD32: 10 | AE32: $5 | AF32: 8 | AG32: 10 | AH32: 11 | AI32: 10 | AJ32: 20 | AK32: 5 | AL32: 5 | AM32: 1 | AN32: 2 | AO32: 3 | AP32: 1 | AQ32: 2 | AR32: 3 | AS32: 1 | AT32: 2 | AU32: 1 | AV32: 1 | AW32: 2 | AX32: 10 | AY32: 9 | AZ32: 6 | BA32: 3 | BB32: 5 | BC32: 12 | BD32: 9 | BE32: 5 | BF32: 1 | BG32: 3 | BH32: 9 | BI32: 3 | BJ32: 3 | BK32: 5 | BL32: 3 | BM32: 1 | BN32: 1 | BO32: 1 | BP32: 3 | BQ32: 1 | BR32: 10 | BS32: 1 | BT32: 3 | BU32: 9 | BV32: 4 | BW32: 1 | BX32: 7 | BY32: 3 | BZ32: 1 | CA32: 1 | CB32: 20 | CC32: 1 | CD32: 1 | CE32: 4 | CF32: 1 | CG32: 1 | CH32: 1
A33: 44 | C33: Benjamin Martin-Coward | D33: DM/M C | E33: England | F33: 45 | G33: 84 | H33: 20 | I33: 1745 | J33: $0 | K33: 8304 | L33: False | M33: False | N33: -159 | O33: 8800 | P33: 7 | Q33: 12 | R33: 10 | S33: 7 | T33: 9 | U33: 10 | V33: 10 | W33: 10 | X33: 10 | Y33: 10 | Z33: 10 | AA33: 10 | AB33: 10 | AC33: 13 | AD33: 9 | AE33: $5 | AF33: 6 | AG33: 7 | AH33: 12 | AI33: 13 | AJ33: 20 | AK33: 9 | AL33: 1 | AM33: 1 | AN33: 1 | AO33: 3 | AP33: 2 | AQ33: 1 | AR33: 3 | AS33: 1 | AT33: 2 | AU33: 2 | AV33: 1 | AW33: 3 | AX33: 10 | AY33: 7 | AZ33: 4 | BA33: 5 | BB33: 4 | BC33: 10 | BD33: 12 | BE33: 5 | BF33: 6 | BG33: 5 | BH33: 7 | BI33: 6 | BJ33: 14 | BK33: 7 | BL33: 4 | BM33: 1 | BN33: 3 | BO33: 4 | BP33: 11 | BQ33: 3 | BR33: 4 | BS33: 8 | BT33: 1 | BU33: 8 | BV33: 11 | BW33: 1 | BX33: 5 | BY33: 6 | BZ33: 1 | CA33: 1 | CB33: 1 | CC33: 1 | CD33: 20 | CE33: 1 | CF33: 1 | CG33: 1 | CH33: 1
A34: -1 | C34: Brogan Popham | D34: D/WB/M L | E34: Wales | F34: 55 | G34: 90 | H34: 19 | I34: 746 | J34: $0 | K34: 10000 | L34: False | M34: False | N34: -224 | O34: 6250 | P34: 6 | Q34: 5 | R34: 9 | S34: 6 | T34: 9 | U34: 10 | V34: 10 | W34: 10 | X34: 10 | Y34: 10 | Z34: 10 | AA34: 10 | AB34: 10 | AC34: 13 | AD34: 11 | AE34: $5 | AF34: 8 | AG34: 10 | AH34: 15 | AI34: 12 | AJ34: 20 | AK34: 14 | AL34: 6 | AM34: 1 | AN34: 2 | AO34: 1 | AP34: 1 | AQ34: 3 | AR34: 2 | AS34: 1 | AT34: 2 | AU34: 3 | AV34: 3 | AW34: 3 | AX34: 7 | AY34: 6 | AZ34: 6 | BA34: 4 | BB34: 7 | BC34: 8 | BD34: 12 | BE34: 7 | BF34: 3 | BG34: 5 | BH34: 5 | BI34: 7 | BJ34: 6 | BK34: 8 | BL34: 4 | BM34: 6 | BN34: 6 | BO34: 1 | BP34: 9 | BQ34: 5 | BR34: 3 | BS34: 2 | BT34: 5 | BU34: 6 | BV34: 6 | BW34: 4 | BX34: 8 | BY34: 7 | BZ34: 1 | CA34: 1 | CB34: 1 | CC34: 16 | CD34: 1 | CE34: 1 | CF34: 1 | CG34: 10 | CH34: 1
... A70: 58 | C70: Danny Stewart | D70: AM/ST RC | E70: England,Northern Ireland | F70: 31 | G70: 73 | H70: 16 | I70: 610 | J70: $1,441 | K70: 9237 | L70: False | M70: False | N70: 88 | O70: 9800 | P70: 4 | Q70: 13 | R70: 9 | S70: 9 | T70: 9 | U70: 6 | V70: 5 | W70: 9 | X70: 14 | Y70: 11 | Z70: 12 | AA70: 13 | AB70: 11 | AC70: 14 | AD70: 11 | AE70: $7 | AF70: 4 | AG70: 8 | AH70: 13 | AI70: 11 | AJ70: 20 | AK70: 7 | AL70: 2 | AM70: 3 | AN70: 2 | AO70: 2 | AP70: 3 | AQ70: 1 | AR70: 2 | AS70: 4 | AT70: 3 | AU70: 1 | AV70: 3 | AW70: 1 | AX70: 10 | AY70: 2 | AZ70: 18 | BA70: 4 | BB70: 2 | BC70: 5 | BD70: 3 | BE70: 8 | BF70: 4 | BG70: 7 | BH70: 1 | BI70: 14 | BJ70: 3 | BK70: 10 | BL70: 3 | BM70: 7 | BN70: 3 | BO70: 5 | BP70: 3 | BQ70: 1 | BR70: 4 | BS70: 2 | BT70: 1 | BU70: 5 | BV70: 7 | BW70: 4 | BX70: 1 | BY70: 8 | BZ70: 1 | CA70: 1 | CB70: 1 | CC70: 1 | CD70: 1 | CE70: 16 | CF70: 16 | CG70: 1 | CH70: 20
A71: -1 | C71: Erdal Peker | D71: AM R | E71: England,Turkey | F71: 57 | G71: 98 | H71: 17 | I71: 1055 | J71: $3,415 | K71: 9538 | L71: False | M71: False | N71: 35 | O71: 10000 | P71: 6 | Q71: 12 | R71: 12 | S71: 3 | T71: 11 | U71: 5 | V71: 10 | W71: 11 | X71: 10 | Y71: 12 | Z71: 11 | AA71: 9 | AB71: 10 | AC71: 15 | AD71: 13 | AE71: $13 | AF71: 4 | AG71: 10 | AH71: 13 | AI71: 13 | AJ71: 20 | AK71: 9 | AL71: 2 | AM71: 3 | AN71: 3 | AO71: 2 | AP71: 2 | AQ71: 3 | AR71: 3 | AS71: 1 | AT71: 1 | AU71: 1 | AV71: 2 | AW71: 1 | AX71: 9 | AY71: 5 | AZ71: 8 | BA71: 5 | BB71: 3 | BC71: 6 | BD71: 8 | BE71: 12 | BF71: 6 | BG71: 7 | BH71: 1 | BI71: 2 | BJ71: 7 | BK71: 7 | BL71: 3 | BM71: 6 | BN71: 5 | BO71: 6 | BP71: 13 | BQ71: 1 | BR71: 1 | BS71: 2 | BT71: 3 | BU71: 2 | BV71: 7 | BW71: 2 | BX71: 1 | BY71: 11 | BZ71: 1 | CA71: 1 | CB71: 1 | CC71: 1 | CD71: 1 | CE71: 20 | CF71: 10 | CG71: 1 | CH71: 1 | CI71: Mousehole AFC
A72: 61 | C72: Henry Gregory | D72: M/AM L | E72: England | F72: 61 | G72: 90 | H72: 16 | I72: 1117 | J72: $2,298 | K72: 10000 | L72: False | M72: False | N72: 73 | O72: 6600 | P72: 7 | Q72: 16 | R72: 12 | S72: 9 | T72: 9 | U72: 7 | V72: 17 | W72: 12 | X72: 17 | Y72: 18 | Z72: 17 | AA72: 17 | AB72: 17 | AC72: 13 | AD72: 14 | AE72: $7 | AF72: 1 | AG72: 9 | AH72: 14 | AI72: 12 | AJ72: 20 | AK72: 12 | AL72: 3 | AM72: 3 | AN72: 2 | AO72: 3 | AP72: 2 | AQ72: 2 | AR72: 3 | AS72: 1 | AT72: 2 | AU72: 2 | AV72: 1 | AW72: 4 | AX72: 11 | AY72: 6 | AZ72: 8 | BA72: 6 | BB72: 3 | BC72: 6 | BD72: 8 | BE72: 14 | BF72: 4 | BG72: 7 | BH72: 2 | BI72: 7 | BJ72: 7 | BK72: 6 | BL72: 4 | BM72: 9 | BN72: 8 | BO72: 5 | BP72: 9 | BQ72: 8 | BR72: 9 | BS72: 3 | BT72: 1 | BU72: 5 | BV72: 6 | BW72: 4 | BX72: 2 | BY72: 13 | BZ72: 1 | CA72: 2 | CB72: 1 | CC72: 2 | CD72: 1 | CE72: 1 | CF72: 1 | CG72: 16 | CH72: 1
A73: 51 | C73: Jowan Purnell | D73: DM/M/AM C | E73: England,Northern Ireland | F73: 63 | G73: 95 | H73: 16 | I73: 1134 | J73: $2,306 | K73: 5880 | L73: False | M73: False | N73: 175 | O73: 10000 | P73: 6 | Q73: 6 | R73: 13 | S73: 11 | T73: 9 | U73: 12 | V73: 15 | W73: 4 | X73: 19 | Y73: 18 | Z73: 18 | AA73: 19 | AB73: 18 | AC73: 9 | AD73: 10 | AE73: $12 | AF73: 8 | AG73: 9 | AH73: 4 | AI73: 9 | AJ73: 20 | AK73: 12 | AL73: 5 | AM73: 1 | AN73: 4 | AO73: 3 | AP73: 3 | AQ73: 1 | AR73: 2 | AS73: 2 | AT73: 2 | AU73: 1 | AV73: 1 | AW73: 3 | AX73: 12 | AY73: 6 | AZ73: 5 | BA73: 8 | BB73: 6 | BC73: 13 | BD73: 3 | BE73: 9 | BF73: 7 | BG73: 9 | BH73: 10 | BI73: 8 | BJ73: 11 | BK73: 6 | BL73: 8 | BM73: 6 | BN73: 5 | BO73: 5 | BP73: 11 | BQ73: 4 | BR73: 1 | BS73: 6 | BT73: 4 | BU73: 8 | BV73: 14 | BW73: 6 | BX73: 8 | BY73: 6 | BZ73: 1 | CA73: 1 | CB73: 1 | CC73: 1 | CD73: 20 | CE73: 1 | CF73: 16 | CG73: 1 | CH73: 1
A74: 60 | C74: Mamadou Kanté | D74: D RL | E74: England,Guinea | F74: 44 | G74: 63 | H74: 16 | I74: 998 | J74: $2,005 | K74: 9150 | L74: False | M74: False | N74: 87 | O74: 9200 | P74: 6 | Q74: 11 | R74: 7 | S74: 7 | T74: 12 | U74: 12 | V74: 3 | W74: 8 | X74: 13 | Y74: 8 | Z74: 11 | AA74: 11 | AB74: 12 | AC74: 11 | AD74: 9 | AE74: $8 | AF74: 9 | AG74: 20 | AH74: 11 | AI74: 10 | AJ74: 7 | AK74: 12 | AL74: 4 | AM74: 3 | AN74: 2 | AO74: 3 | AP74: 3 | AQ74: 3 | AR74: 3 | AS74: 1 | AT74: 1 | AU74: 3 | AV74: 2 | AW74: 3 | AX74: 10 | AY74: 8 | AZ74: 10 | BA74: 5 | BB74: 9 | BC74: 11 | BD74: 3 | BE74: 5 | BF74: 14 | BG74: 7 | BH74: 9 | BI74: 13 | BJ74: 5 | BK74: 8 | BL74: 5 | BM74: 7 | BN74: 7 | BO74: 1 | BP74: 6 | BQ74: 3 | BR74: 4 | BS74: 4 | BT74: 4 | BU74: 5 | BV74: 5 | BW74: 2 | BX74: 7 | BY74: 6 | BZ74: 1 | CA74: 16 | CB74: 1 | CC74: 20 | CD74: 1 | CE74: 1 | CF74: 1 | CG74: 1 | CH74: 1
A75: 23 | C75: Nathan Vaughan | D75: M/AM R | E75: England | F75: 37 | G75: 97 | H75: 16 | I75: 790 | J75: $1,774 | K75: 9601 | L75: False | M75: False | N75: 82 | O75: 10000 | P75: 6 | Q75: 15 | R75: 10 | S75: 9 | T75: 14 | U75: 12 | V75: 16 | W75: 9 | X75: 18 | Y75: 16 | Z75: 17 | AA75: 17 | AB75: 18 | AC75: 11 | AD75: 8 | AE75: $13 | AF75: 9 | AG75: 9 | AH75: 15 | AI75: 8 | AJ75: 20 | AK75: 11 | AL75: 7 | AM75: 3 | AN75: 2 | AO75: 2 | AP75: 1 | AQ75: 2 | AR75: 1 | AS75: 3 | AT75: 1 | AU75: 1 | AV75: 1 | AW75: 4 | AX75: 18 | AY75: 7 | AZ75: 5 | BA75: 6 | BB75: 4 | BC75: 5 | BD75: 5 | BE75: 10 | BF75: 6 | BG75: 5 | BH75: 4 | BI75: 10 | BJ75: 4 | BK75: 7 | BL75: 7 | BM75: 12 | BN75: 7 | BO75: 4 | BP75: 5 | BQ75: 11 | BR75: 1 | BS75: 3 | BT75: 3 | BU75: 3 | BV75: 8 | BW75: 6 | BX75: 3 | BY75: 7 | BZ75: 1 | CA75: 1 | CB75: 1 | CC75: 1 | CD75: 1 | CE75: 16 | CF75: 1 | CG75: 1 | CH75: 1
A76: 32 | C76: Paul Jarvis | D76: M/AM RL | E76: Wales,England | F76: 64 | G76: 86 | H76: 17 | I76: 924 | J76: $0 | K76: 8614 | L76: False | M76: False | N76: 41 | O76: 10000 | P76: 6 | Q76: 10 | R76: 9 | S76: 12 | T76: 9 | U76: 17 | V76: 6 | W76: 6 | X76: 11 | Y76: 9 | Z76: 14 | AA76: 11 | AB76: 11 | AC76: 11 | AD76: 14 | AE76: $10 | AF76: 3 | AG76: 20 | AH76: 7 | AI76: 14 | AJ76: 8 | AK76: 12 | AL76: 5 | AM76: 2 | AN76: 3 | AO76: 1 | AP76: 2 | AQ76: 3 | AR76: 3 | AS76: 1 | AT76: 3 | AU76: 2 | AV76: 1 | AW76: 2 | AX76: 12 | AY76: 7 | AZ76: 8 | BA76: 5 | BB76: 3 | BC76: 7 | BD76: 4 | BE76: 9 | BF76: 7 | BG76: 8 | BH76: 1 | BI76: 9 | BJ76: 5 | BK76: 14 | BL76: 4 | BM76: 9 | BN76: 11 | BO76: 5 | BP76: 7 | BQ76: 8 | BR76: 1 | BS76: 4 | BT76: 3 | BU76: 2 | BV76: 6 | BW76: 1 | BX76: 3 | BY76: 8 | BZ76: 1 | CA76: 1 | CB76: 1 | CC76: 1 | CD76: 1 | CE76: 4 | CF76: 3 | CG76: 20 | CH76: 1
A77: -1 | C77: Scott Aldridge | D77: M/AM RL | E77: England | F77: 54 | G77: 59 | H77: 17 | I77: 1215 | J77: $3,337 | K77: 9369 | L77: False | M77: False | N77: 27 | O77: 9900 | P77: 9 | Q77: 5 | R77: 13 | S77: 2 | T77: 13 | U77: 14 | V77: 8 | W77: 10 | X77: 11 | Y77: 12 | Z77: 3 | AA77: 12 | AB77: 13 | AC77: 15 | AD77: 11 | AE77: $6 | AF77: 5 | AG77: 11 | AH77: 16 | AI77: 13 | AJ77: 20 | AK77: 10 | AL77: 3 | AM77: 3 | AN77: 3 | AO77: 1 | AP77: 3 | AQ77: 2 | AR77: 3 | AS77: 1 | AT77: 3 | AU77: 1 | AV77: 3 | AW77: 1 | AX77: 8 | AY77: 4 | AZ77: 4 | BA77: 5 | BB77: 3 | BC77: 5 | BD77: 4 | BE77: 6 | BF77: 9 | BG77: 6 | BH77: 3 | BI77: 6 | BJ77: 6 | BK77: 5 | BL77: 4 | BM77: 8 | BN77: 8 | BO77: 4 | BP77: 7 | BQ77: 4 | BR77: 5 | BS77: 5 | BT77: 3 | BU77: 3 | BV77: 6 | BW77: 1 | BX77: 4 | BY77: 10 | BZ77: 1 | CA77: 2 | CB77: 1 | CC77: 1 | CD77: 1 | CE77: 20 | CF77: 1 | CG77: 13 | CH77: 1 | CI77: Tonbridge Angels
A78: 5 | C78: Tyler Stalley | D78: D RC | E78: England | F78: 65 | G78: 91 | H78: 16 | I78: 1120 | J78: $2,178 | K78: 6430 | L78: False | M78: False | N78: 158 | O78: 10000 | P78: 15 | Q78: 13 | R78: 12 | S78: 2 | T78: 11 | U78: 13 | V78: 17 | W78: 8 | X78: 17 | Y78: 17 | Z78: 17 | AA78: 18 | AB78: 18 | AC78: 7 | AD78: 8 | AE78: $13 | AF78: 12 | AG78: 9 | AH78: 9 | AI78: 10 | AJ78: 20 | AK78: 7 | AL78: 9 | AM78: 2 | AN78: 2 | AO78: 3 | AP78: 3 | AQ78: 1 | AR78: 2 | AS78: 3 | AT78: 3 | AU78: 1 | AV78: 3 | AW78: 1 | AX78: 11 | AY78: 11 | AZ78: 7 | BA78: 3 | BB78: 10 | BC78: 8 | BD78: 11 | BE78: 8 | BF78: 8 | BG78: 6 | BH78: 12 | BI78: 7 | BJ78: 6 | BK78: 6 | BL78: 4 | BM78: 8 | BN78: 3 | BO78: 5 | BP78: 8 | BQ78: 5 | BR78: 12 | BS78: 4 | BT78: 2 | BU78: 15 | BV78: 6 | BW78: 2 | BX78: 10 | BY78: 5 | BZ78: 1 | CA78: 19 | CB78: 20 | CC78: 5 | CD78: 1 | CE78: 1 | CF78: 1 | CG78: 1 | CH78: 1

Sheet Display
A1: Name | B1: Best Position | C1: Age | D1: CA | E1: PA | F1: Nationalities | G1: Club | H1: Asking Price | I1: Positions | J1: Striker | K1: AM(L) | L1: AM(C) | M1: AM(R) | N1: DM(L) | O1: DM(R) | P1: D(C) | Q1: D(R/L) | R1: GK | S1: Acceleration | T1: Agility | U1: Balance | V1: Jumping | W1: Natural Fitness | X1: Pace | Y1: Stamina | Z1: Strength | AA1: Aerial Ability | AB1: Command of Area | AC1: Communication | AD1: Eccentricity | AE1: Handling | AF1: Kicking | AG1: One on Ones | AH1: Tendency to Punch | AI1: Reflexes | AJ1: Rushing Out | AK1: Throwing | AL1: Aggression | AM1: Anticipation | AN1: Bravery | AO1: Composure | AP1: Concentration | AQ1: Decisions | AR1: Determination | AS1: Flair | AT1: Leadership | AU1: Off The Ball | AV1: Positioning | AW1: Teamwork | AX1: Vision | AY1: Work Rate | AZ1: Crossing | BA1: Dribbling | BB1: Finishing | BC1: First Touch | BD1: Heading | BE1: Long Shots | BF1: Marking | BG1: Passing | BH1: Tackling | BI1: Technique | BJ1: Corners | BK1: Free Kicks | BL1: Long Throws | BM1: Penalty Taking
A2: =IF(ISBLANK('Paste Full'!C2),"",'Paste Full'!C2) | B2: =INDEX($J$1:$R$1, MATCH(MAX($J2:$R2), $J2:$R2, 0)) | C2: =IF(ISBLANK('Paste Full'!H2),"",'Paste Full'!H2) | D2: =IF(ISBLANK('Paste Full'!F2),"",'Paste Full'!F2) | E2: =IF(ISBLANK('Paste Full'!G2),"",'Paste Full'!G2) | F2: =IF(ISBLANK('Paste Full'!E2),"",'Paste Full'!E2) | G2: =IF(ISBLANK('Paste Full'!CI2),"",'Paste Full'!CI2) | H2: =IF(ISBLANK('Paste Full'!J2),"",'Paste Full'!J2) | I2: =IF(ISBLANK('Paste Full'!D2),"",'Paste Full'!D2) | J2: =AVERAGE(SUMPRODUCT($S2:$BM2,AttWeights!$C$10:$AW$10)/SUM(AttWeights!$C$10:$AW$10),SUMPRODUCT($S2:$BM2,AttWeights!$C$17:$AW$17)/SUM(AttWeights!$C$17:$AW$17))*10 | K2: =AVERAGE(SUMPRODUCT($S2:$BM2,AttWeights!$C$7:$AW$7)/SUM(AttWeights!$C$7:$AW$7),SUMPRODUCT($S2:$BM2,AttWeights!$C$15:$AW$15)/SUM(AttWeights!$C$15:$AW$15))*10 | L2: =AVERAGE(SUMPRODUCT($S2:$BM2,AttWeights!$C$8:$AW$8)/SUM(AttWeights!$C$8:$AW$8),SUMPRODUCT($S2:$BM2,AttWeights!$C$16:$AW$16)/SUM(AttWeights!$C$16:$AW$16))*10 | M2: =AVERAGE(SUMPRODUCT($S2:$BM2,AttWeights!$C$9:$AW$9)/SUM(AttWeights!$C$9:$AW$9),SUMPRODUCT($S2:$BM2,AttWeights!$C$15:$AW$15)/SUM(AttWeights!$C$15:$AW$15))*10 | N2: =AVERAGE(SUMPRODUCT($S2:$BM2,AttWeights!$C$6:$AW$6)/SUM(AttWeights!$C$6:$AW$6),SUMPRODUCT($S2:$BM2,AttWeights!$C$14:$AW$14)/SUM(AttWeights!$C$14:$AW$14))*10 | O2: =AVERAGE(SUMPRODUCT($S2:$BM2,AttWeights!$C$5:$AW$5)/SUM(AttWeights!$C$5:$AW$5),SUMPRODUCT($S2:$BM2,AttWeights!$C$14:$AW$14)/SUM(AttWeights!$C$14:$AW$14))*10 | P2: =AVERAGE(SUMPRODUCT($S2:$BM2,AttWeights!$C$4:$AW$4)/SUM(AttWeights!$C$4:$AW$4),SUMPRODUCT($S2:$BM2,AttWeights!$C$13:$AW$13)/SUM(AttWeights!$C$13:$AW$13))*10 | Q2: =AVERAGE(SUMPRODUCT($S2:$BM2,AttWeights!$C$3:$AW$3)/SUM(AttWeights!$C$3:$AW$3),SUMPRODUCT($S2:$BM2,AttWeights!$C$12:$AW$12)/SUM(AttWeights!$C$12:$AW$12))*10 | R2: =AVERAGE(SUMPRODUCT($S2:$BM2,AttWeights!$C$2:$AW$2)/SUM(AttWeights!$C$2:$AW$2),SUMPRODUCT($S2:$BM2,AttWeights!$C$11:$AW$11)/SUM(AttWeights!$C$11:$AW$11))*10 | S2: =IF(ISBLANK('Paste Full'!AC2),"",'Paste Full'!AC2) | T2: =IF(ISBLANK('Paste Full'!AD2),"",'Paste Full'!AD2) | U2: =IF(ISBLANK('Paste Full'!AE2),"",'Paste Full'!AE2) | V2: =IF(ISBLANK('Paste Full'!AF2),"",'Paste Full'!AF2) | W2: =IF(ISBLANK('Paste Full'!AH2),"",'Paste Full'!AH2) | X2: =IF(ISBLANK('Paste Full'!AI2),"",'Paste Full'!AI2) | Y2: =IF(ISBLANK('Paste Full'!AK2),"",'Paste Full'!AK2) | Z2: =IF(ISBLANK('Paste Full'!AL2),"",'Paste Full'!AL2) | AA2: =IF(ISBLANK('Paste Full'!AM2),"",'Paste Full'!AM2) | AB2: =IF(ISBLANK('Paste Full'!AN2),"",'Paste Full'!AN2) | AC2: =IF(ISBLANK('Paste Full'!AO2),"",'Paste Full'!AO2) | AD2: =IF(ISBLANK('Paste Full'!AP2),"",'Paste Full'!AP2) | AE2: =IF(ISBLANK('Paste Full'!AQ2),"",'Paste Full'!AQ2) | AF2: =IF(ISBLANK('Paste Full'!AR2),"",'Paste Full'!AR2) | AG2: =IF(ISBLANK('Paste Full'!AS2),"",'Paste Full'!AS2) | AH2: =IF(ISBLANK('Paste Full'!AV2),"",'Paste Full'!AV2) | AI2: =IF(ISBLANK('Paste Full'!AT2),"",'Paste Full'!AT2) | AJ2: =IF(ISBLANK('Paste Full'!AU2),"",'Paste Full'!AU2) | AK2: =IF(ISBLANK('Paste Full'!AW2),"",'Paste Full'!AW2) | AL2: =IF(ISBLANK('Paste Full'!AX2),"",'Paste Full'!AX2) | AM2: =IF(ISBLANK('Paste Full'!AY2),"",'Paste Full'!AY2) | AN2: =IF(ISBLANK('Paste Full'!AZ2),"",'Paste Full'!AZ2) | AO2: =IF(ISBLANK('Paste Full'!BA2),"",'Paste Full'!BA2) | AP2: =IF(ISBLANK('Paste Full'!BB2),"",'Paste Full'!BB2) | AQ2: =IF(ISBLANK('Paste Full'!BC2),"",'Paste Full'!BC2) | AR2: =IF(ISBLANK('Paste Full'!BD2),"",'Paste Full'!BD2) | ... AY2: =IF(ISBLANK('Paste Full'!BK2),"",'Paste Full'!BK2) | AZ2: =IF(ISBLANK('Paste Full'!BM2),"",'Paste Full'!BM2) | BA2: =IF(ISBLANK('Paste Full'!BN2),"",'Paste Full'!BN2) | BB2: =IF(ISBLANK('Paste Full'!BO2),"",'Paste Full'!BO2) | BC2: =IF(ISBLANK('Paste Full'!BP2),"",'Paste Full'!BP2) | BD2: =IF(ISBLANK('Paste Full'!BR2),"",'Paste Full'!BR2) | BE2: =IF(ISBLANK('Paste Full'!BS2),"",'Paste Full'!BS2) | BF2: =IF(ISBLANK('Paste Full'!BU2),"",'Paste Full'!BU2) | BG2: =IF(ISBLANK('Paste Full'!BV2),"",'Paste Full'!BV2) | BH2: =IF(ISBLANK('Paste Full'!BX2),"",'Paste Full'!BX2) | BI2: =IF(ISBLANK('Paste Full'!BY2),"",'Paste Full'!BY2) | BJ2: =IF(ISBLANK('Paste Full'!BL2),"",'Paste Full'!BL2) | BK2: =IF(ISBLANK('Paste Full'!BQ2),"",'Paste Full'!BQ2) | BL2: =IF(ISBLANK('Paste Full'!BT2),"",'Paste Full'!BT2) | BM2: =IF(ISBLANK('Paste Full'!BW2),"",'Paste Full'!BW2)
